Workbook
Name AprStart: WEEKDAY(DATE(_xleta.Year,4,1))
Name AprStart: WEEKDAY(DATE(_xleta.Year,4,1))
Name AprStart: WEEKDAY(DATE(_xleta.Year,4,1))
Name AprStart: WEEKDAY(DATE(_xleta.Year,4,1))
Name AprStart: WEEKDAY(DATE(_xleta.Year,4,1))
Name AprStart: WEEKDAY(DATE(_xleta.Year,4,1))
Name AprStart: WEEKDAY(DATE(_xleta.Year,4,1))
Name AprStart: WEEKDAY(DATE(_xleta.Year,4,1))
Name AprStart: WEEKDAY(DATE(_xleta.Year,4,1))
Name AprStart: WEEKDAY(DATE(_xleta.Year,4,1))
Name AugStart: WEEKDAY(DATE(_xleta.Year,8,1))
Name AugStart: WEEKDAY(DATE(_xleta.Year,8,1))
Name AugStart: WEEKDAY(DATE(_xleta.Year,8,1))
Name AugStart: WEEKDAY(DATE(_xleta.Year,8,1))
Name AugStart: WEEKDAY(DATE(_xleta.Year,8,1))
Name AugStart: WEEKDAY(DATE(_xleta.Year,8,1))
Name AugStart: WEEKDAY(DATE(_xleta.Year,8,1))
Name AugStart: WEEKDAY(DATE(_xleta.Year,8,1))
Name AugStart: WEEKDAY(DATE(_xleta.Year,8,1))
Name AugStart: WEEKDAY(DATE(_xleta.Year,8,1))
Name BUDGET_Title: #REF!
Name ColumnTitle1: #REF!
Name COMPANY_NAME: #REF!
Name DecStart: WEEKDAY(DATE(_xleta.Year,12,1))
Name DecStart: WEEKDAY(DATE(_xleta.Year,12,1))
Name DecStart: WEEKDAY(DATE(_xleta.Year,12,1))
Name DecStart: WEEKDAY(DATE(_xleta.Year,12,1))
Name DecStart: WEEKDAY(DATE(_xleta.Year,12,1))
Name DecStart: WEEKDAY(DATE(_xleta.Year,12,1))
Name DecStart: WEEKDAY(DATE(_xleta.Year,12,1))
Name DecStart: WEEKDAY(DATE(_xleta.Year,12,1))
Name DecStart: WEEKDAY(DATE(_xleta.Year,12,1))
Name DecStart: WEEKDAY(DATE(_xleta.Year,12,1))
Name FebStart: WEEKDAY(DATE(_xleta.Year,2,1))
Name FebStart: WEEKDAY(DATE(_xleta.Year,2,1))
Name FebStart: WEEKDAY(DATE(_xleta.Year,2,1))
Name FebStart: WEEKDAY(DATE(_xleta.Year,2,1))
Name FebStart: WEEKDAY(DATE(_xleta.Year,2,1))
Name FebStart: WEEKDAY(DATE(_xleta.Year,2,1))
Name FebStart: WEEKDAY(DATE(_xleta.Year,2,1))
Name FebStart: WEEKDAY(DATE(_xleta.Year,2,1))
Name FebStart: WEEKDAY(DATE(_xleta.Year,2,1))
Name FebStart: WEEKDAY(DATE(_xleta.Year,2,1))
Name IsLeapYear: OR(MOD(_xleta.Year,400)=0,AND(MOD(_xleta.Year,4)=0,MOD(_xleta.Year,100)<>0))
Name IsLeapYear: OR(MOD(_xleta.Year,400)=0,AND(MOD(_xleta.Year,4)=0,MOD(_xleta.Year,100)<>0))
Name IsLeapYear: OR(MOD(_xleta.Year,400)=0,AND(MOD(_xleta.Year,4)=0,MOD(_xleta.Year,100)<>0))
Name IsLeapYear: OR(MOD(_xleta.Year,400)=0,AND(MOD(_xleta.Year,4)=0,MOD(_xleta.Year,100)<>0))
Name IsLeapYear: OR(MOD(_xleta.Year,400)=0,AND(MOD(_xleta.Year,4)=0,MOD(_xleta.Year,100)<>0))
Name IsLeapYear: OR(MOD(_xleta.Year,400)=0,AND(MOD(_xleta.Year,4)=0,MOD(_xleta.Year,100)<>0))
Name IsLeapYear: OR(MOD(_xleta.Year,400)=0,AND(MOD(_xleta.Year,4)=0,MOD(_xleta.Year,100)<>0))
Name IsLeapYear: OR(MOD(_xleta.Year,400)=0,AND(MOD(_xleta.Year,4)=0,MOD(_xleta.Year,100)<>0))
Name IsLeapYear: OR(MOD(_xleta.Year,400)=0,AND(MOD(_xleta.Year,4)=0,MOD(_xleta.Year,100)<>0))
Name IsLeapYear: OR(MOD(_xleta.Year,400)=0,AND(MOD(_xleta.Year,4)=0,MOD(_xleta.Year,100)<>0))
Name JanStart: WEEKDAY(DATE(_xleta.Year,1,1))
Name JanStart: WEEKDAY(DATE(_xleta.Year,1,1))
Name JanStart: WEEKDAY(DATE(_xleta.Year,1,1))
Name JanStart: WEEKDAY(DATE(_xleta.Year,1,1))
Name JanStart: WEEKDAY(DATE(_xleta.Year,1,1))
Name JanStart: WEEKDAY(DATE(_xleta.Year,1,1))
Name JanStart: WEEKDAY(DATE(_xleta.Year,1,1))

Sheet Manu

Sheet All Exp  (3)
A1: Month | B1: Salaries | C1: Utilities | D1: Fuel | E1: Petty | F1: Rent | G1: Tax & P | H1: Purchase | I1: Incentive | J1: Comm | K1: Repair | M1: Non | N1: Other | O1: Adjust | P1: RTGS | AH1: RTGS | AN1: Credit | AO1: Cr Paid | AP1: Cr Payable | AQ1: Loan | AR1: Loan Paid | AS1: L Payable | AT1: T Liabelity | AU1: Whl Pur | AV1: DC | AW1: Adjust | AX1: RTGS | AY1: Outflow (sum of Debit) | BD1: Month | BE1: Inflows (Credit) | BF1: Outflows (Debit) | BG1: Closing Balance
A2: 2018-11 | B2: =SUMIFS(Trans!$D:$D,Trans!$F:$F,$B$1,Trans!$I:$I,$A2,Trans!$C:$C,"Debit") -> 0 | C2: =SUMIFS(Trans!$D:$D,Trans!$F:$F,C$1,Trans!$I:$I,$A2,Trans!$C:$C,"Debit") -> 0 | D2: =SUMIFS(Trans!$D:$D,Trans!$F:$F,D$1,Trans!$I:$I,$A2,Trans!$C:$C,"Debit") -> 30000 | E2: =SUMIFS(Trans!$D:$D,Trans!$F:$F,E$1,Trans!$I:$I,$A2,Trans!$C:$C,"Debit") -> 0 | F2: =SUMIFS(Trans!$D:$D,Trans!$F:$F,F$1,Trans!$I:$I,$A2,Trans!$C:$C,"Debit") -> 0 | G2: =SUMIFS(Trans!$D:$D,Trans!$H:$H,G$1,Trans!$I:$I,$A2,Trans!$C:$C,"Debit") -> 0 | H2: =SUMIFS(Trans!$D:$D,Trans!$G:$G,H$1,Trans!$I:$I,$A2,Trans!$C:$C,"Debit") -> 0 | I2: =SUMIFS(Trans!$D:$D,Trans!$G:$G,I$1,Trans!$I:$I,$A2,Trans!$C:$C,"Debit") -> 0 | J2: =SUMIFS(Trans!$D:$D,Trans!$G:$G,J$1,Trans!$I:$I,$A2,Trans!$C:$C,"Debit") -> 0 | K2: =SUMIFS(Trans!$D:$D,Trans!$G:$G,K$1,Trans!$I:$I,$A2,Trans!$C:$C,"Debit") -> 0 | M2: =SUMIFS(Trans!$D:$D,Trans!$G:$G,M$1,Trans!$I:$I,$A2,Trans!$C:$C,"Debit") -> 0 | N2: =SUMIFS(Trans!$D:$D,Trans!$G:$G,N$1,Trans!$I:$I,$A2,Trans!$C:$C,"Debit") -> 0 | O2: =SUMIFS(Trans!$D:$D,Trans!$G:$G,E$1,Trans!$I:$I,$A17,Trans!$C:$C,"Debit") -> 0 | P2: =SUMIFS(Trans!$D:$D,Trans!$G:$G,M$1,Trans!$I:$I,$A17,Trans!$C:$C,"Debit")-SUMIFS(Trans!$D:$D,Trans!$G:$G,AX$1,Trans!$I:$I,$A17,Trans!$C:$C,"Credit") -> 0 | AH2: =SUMIFS(Trans!$D:$D,Trans!$G:$G,AH$1,Trans!$I:$I,$A2,Trans!$C:$C,"Credit") -> 0 | AN2: =SUMIFS(Trans!$D:$D,Trans!$G:$G,AN$1,Trans!$I:$I,$A2,Trans!$C:$C,"Debit") -> 0 | AO2: =SUMIFS(Trans!$D:$D,Trans!$G:$G,AO$1,Trans!$I:$I,$A2,Trans!$C:$C,"Credit") -> 0 | AP2: =AO2-AN2 -> 0 | AQ2: =SUMIFS(Trans!$D:$D,Trans!$G:$G,AQ$1,Trans!$I:$I,$A2,Trans!$C:$C,"Debit") -> 0 | AR2: =SUMIFS(Trans!$D:$D,Trans!$G:$G,AR$1,Trans!$I:$I,$A2,Trans!$C:$C,"Credit") -> 0 | AU2: =SUMIFS(Trans!$D:$D,Trans!$G:$G,AU$1,Trans!$I:$I,$A2,Trans!$C:$C,"Debit") -> 0 | AV2: {=SUM(SUMIFS(Trans!$D:$D,Trans!$H:$H,{"LC","DC","Customs duty","Freight ","Insurance","Related"},Trans!$I:$I,$A2,Trans!$C:$C,"Debit"))} -> 0 | AW2: =SUMIFS(Trans!$D:$D,Trans!$G:$G,AQ$1,Trans!$I:$I,$A2,Trans!$C:$C,"Debit") -> 0 | AX2: =SUMIFS(Trans!$D:$D,Trans!$G:$G,AX$1,Trans!$I:$I,$A2,Trans!$C:$C,"Debit")-SUMIFS(Trans!$D:$D,Trans!$G:$G,#REF!,Trans!$I:$I,$A2,Trans!$C:$C,"Credit") -> 0 | BD2: 2017-11 | BE2: =SUMIFS(Trans!$D:$D,Trans!$A:$A,">="&DATE(2017,11,1),Trans!$A:$A,"<"&EDATE(DATE(2017,11,1),1),Trans!$C:$C,"Credit") -> 0 | BF2: =SUMIFS(Trans!$D:$D,Trans!$A:$A,">="&DATE(2017,11,1),Trans!$A:$A,"<"&EDATE(DATE(2017,11,1),1),Trans!$C:$C,"Debit") -> 0 | BG2: 451625
A3: 2018-12 | B3: =SUMIFS(Trans!$D:$D,Trans!$F:$F,$B$1,Trans!$I:$I,$A3,Trans!$C:$C,"Debit") -> 0 | C3: =SUMIFS(Trans!$D:$D,Trans!$F:$F,C$1,Trans!$I:$I,$A3,Trans!$C:$C,"Debit") -> 0 | D3: =SUMIFS(Trans!$D:$D,Trans!$F:$F,D$1,Trans!$I:$I,$A3,Trans!$C:$C,"Debit") -> 0 | E3: =SUMIFS(Trans!$D:$D,Trans!$F:$F,E$1,Trans!$I:$I,$A3,Trans!$C:$C,"Debit") -> 0 | F3: =SUMIFS(Trans!$D:$D,Trans!$F:$F,F$1,Trans!$I:$I,$A3,Trans!$C:$C,"Debit") -> 0 | G3: =SUMIFS(Trans!$D:$D,Trans!$H:$H,G$1,Trans!$I:$I,$A3,Trans!$C:$C,"Debit") -> 0 | H3: =SUMIFS(Trans!$D:$D,Trans!$G:$G,H$1,Trans!$I:$I,$A3,Trans!$C:$C,"Debit") -> 0 | I3: =SUMIFS(Trans!$D:$D,Trans!$G:$G,I$1,Trans!$I:$I,$A3,Trans!$C:$C,"Debit") -> 0 | J3: =SUMIFS(Trans!$D:$D,Trans!$G:$G,J$1,Trans!$I:$I,$A3,Trans!$C:$C,"Debit") -> 0 | K3: =SUMIFS(Trans!$D:$D,Trans!$G:$G,K$1,Trans!$I:$I,$A3,Trans!$C:$C,"Debit") -> 0 | M3: =SUMIFS(Trans!$D:$D,Trans!$G:$G,M$1,Trans!$I:$I,$A3,Trans!$C:$C,"Debit") -> 0 | N3: =SUMIFS(Trans!$D:$D,Trans!$G:$G,N$1,Trans!$I:$I,$A3,Trans!$C:$C,"Debit") -> 0 | O3: =SUMIFS(Trans!$D:$D,Trans!$G:$G,E$1,Trans!$I:$I,$A18,Trans!$C:$C,"Debit") -> 0 | P3: =SUMIFS(Trans!$D:$D,Trans!$G:$G,M$1,Trans!$I:$I,$A18,Trans!$C:$C,"Debit")-SUMIFS(Trans!$D:$D,Trans!$G:$G,AX$1,Trans!$I:$I,$A18,Trans!$C:$C,"Credit") -> 0 | AE3: salary | AF3: 57000 | AH3: =SUMIFS(Trans!$D:$D,Trans!$G:$G,AH$1,Trans!$I:$I,$A3,Trans!$C:$C,"Credit") -> 0 | AN3: =SUMIFS(Trans!$D:$D,Trans!$G:$G,AN$1,Trans!$I:$I,$A3,Trans!$C:$C,"Debit") -> 0 | AO3: =SUMIFS(Trans!$D:$D,Trans!$G:$G,AO$1,Trans!$I:$I,$A3,Trans!$C:$C,"Credit") -> 0 | AP3: =AO3-AN3 -> 0 | AQ3: =SUMIFS(Trans!$D:$D,Trans!$G:$G,AQ$1,Trans!$I:$I,$A3,Trans!$C:$C,"Debit") -> 0 | AR3: =SUMIFS(Trans!$D:$D,Trans!$G:$G,AR$1,Trans!$I:$I,$A3,Trans!$C:$C,"Credit") -> 0 | AU3: =SUMIFS(Trans!$D:$D,Trans!$G:$G,AU$1,Trans!$I:$I,$A3,Trans!$C:$C,"Debit") -> 0 | AV3: =SUM(SUMIFS(Trans!$D:$D,Trans!$H:$H,{"LC","DC","Customs duty","Freight ","Insurance","Related"},Trans!$I:$I,$A3,Trans!$C:$C,"Debit")) -> 0 | AW3: =SUMIFS(Trans!$D:$D,Trans!$G:$G,AQ$1,Trans!$I:$I,$A3,Trans!$C:$C,"Debit") -> 0 | AX3: =SUMIFS(Trans!$D:$D,Trans!$G:$G,AX$1,Trans!$I:$I,$A3,Trans!$C:$C,"Debit")-SUMIFS(Trans!$D:$D,Trans!$G:$G,#REF!,Trans!$I:$I,$A3,Trans!$C:$C,"Credit") -> 0 | AY3: =SUMIFS(Trans!$D:$D,Trans!#REF!,#REF!,Trans!$C:$C,"Debit") -> #REF! | BD3: 2017-12 | BE3: =SUMIFS(Trans!$D:$D,Trans!$A:$A,">="&DATE(2017,12,1),Trans!$A:$A,"<"&EDATE(DATE(2017,12,1),1),Trans!$C:$C,"Credit") -> 0 | BF3: =SUMIFS(Trans!$D:$D,Trans!$A:$A,">="&DATE(2017,12,1),Trans!$A:$A,"<"&EDATE(DATE(2017,12,1),1),Trans!$C:$C,"Debit") -> 0 | BG3: 1175740
A4: 2019-01 | B4: =SUMIFS(Trans!$D:$D,Trans!$F:$F,$B$1,Trans!$I:$I,$A4,Trans!$C:$C,"Debit") -> 0 | C4: =SUMIFS(Trans!$D:$D,Trans!$F:$F,C$1,Trans!$I:$I,$A4,Trans!$C:$C,"Debit") -> 0 | D4: =SUMIFS(Trans!$D:$D,Trans!$F:$F,D$1,Trans!$I:$I,$A4,Trans!$C:$C,"Debit") -> 0 | E4: =SUMIFS(Trans!$D:$D,Trans!$F:$F,E$1,Trans!$I:$I,$A4,Trans!$C:$C,"Debit") -> 0 | F4: =SUMIFS(Trans!$D:$D,Trans!$F:$F,F$1,Trans!$I:$I,$A4,Trans!$C:$C,"Debit") -> 0 | G4: =SUMIFS(Trans!$D:$D,Trans!$H:$H,G$1,Trans!$I:$I,$A4,Trans!$C:$C,"Debit") -> 0 | H4: =SUMIFS(Trans!$D:$D,Trans!$G:$G,H$1,Trans!$I:$I,$A4,Trans!$C:$C,"Debit") -> 0 | I4: =SUMIFS(Trans!$D:$D,Trans!$G:$G,I$1,Trans!$I:$I,$A4,Trans!$C:$C,"Debit") -> 0 | J4: =SUMIFS(Trans!$D:$D,Trans!$G:$G,J$1,Trans!$I:$I,$A4,Trans!$C:$C,"Debit") -> 0 | K4: =SUMIFS(Trans!$D:$D,Trans!$G:$G,K$1,Trans!$I:$I,$A4,Trans!$C:$C,"Debit") -> 0 | M4: =SUMIFS(Trans!$D:$D,Trans!$G:$G,M$1,Trans!$I:$I,$A4,Trans!$C:$C,"Debit") -> 0 | N4: =SUMIFS(Trans!$D:$D,Trans!$G:$G,N$1,Trans!$I:$I,$A4,Trans!$C:$C,"Debit") -> 0 | O4: =SUMIFS(Trans!$D:$D,Trans!$G:$G,E$1,Trans!$I:$I,$A19,Trans!$C:$C,"Debit") -> 0 | P4: =SUMIFS(Trans!$D:$D,Trans!$G:$G,M$1,Trans!$I:$I,$A19,Trans!$C:$C,"Debit")-SUMIFS(Trans!$D:$D,Trans!$G:$G,AX$1,Trans!$I:$I,$A19,Trans!$C:$C,"Credit") -> 0 | AE4: Fuel | AF4: 30000 | AH4: =SUMIFS(Trans!$D:$D,Trans!$G:$G,AH$1,Trans!$I:$I,$A4,Trans!$C:$C,"Credit") -> 0 | AN4: =SUMIFS(Trans!$D:$D,Trans!$G:$G,AN$1,Trans!$I:$I,$A4,Trans!$C:$C,"Debit") -> 0 | AO4: =SUMIFS(Trans!$D:$D,Trans!$G:$G,AO$1,Trans!$I:$I,$A4,Trans!$C:$C,"Credit") -> 0 | AP4: =AO4-AN4 -> 0 | AQ4: =SUMIFS(Trans!$D:$D,Trans!$G:$G,AQ$1,Trans!$I:$I,$A4,Trans!$C:$C,"Debit") -> 0 | AR4: =SUMIFS(Trans!$D:$D,Trans!$G:$G,AR$1,Trans!$I:$I,$A4,Trans!$C:$C,"Credit") -> 0 | AU4: =SUMIFS(Trans!$D:$D,Trans!$G:$G,AU$1,Trans!$I:$I,$A4,Trans!$C:$C,"Debit") -> 0 | AV4: =SUM(SUMIFS(Trans!$D:$D,Trans!$H:$H,{"LC","DC","Customs duty","Freight ","Insurance","Related"},Trans!$I:$I,$A4,Trans!$C:$C,"Debit")) -> 0 | AW4: =SUMIFS(Trans!$D:$D,Trans!$G:$G,AQ$1,Trans!$I:$I,$A4,Trans!$C:$C,"Debit") -> 0 | AX4: =SUMIFS(Trans!$D:$D,Trans!$G:$G,AX$1,Trans!$I:$I,$A4,Trans!$C:$C,"Debit")-SUMIFS(Trans!$D:$D,Trans!$G:$G,#REF!,Trans!$I:$I,$A4,Trans!$C:$C,"Credit") -> 0 | AY4: =SUMIFS(Trans!$D:$D,Trans!#REF!,#REF!,Trans!$C:$C,"Debit") -> #REF! | AZ4: #VALUE! | BD4: 2018-01 | BE4: =SUMIFS(Trans!$D:$D,Trans!$A:$A,">="&DATE(2018,1,1),Trans!$A:$A,"<"&EDATE(DATE(2018,1,1),1),Trans!$C:$C,"Credit") -> 0 | BF4: =SUMIFS(Trans!$D:$D,Trans!$A:$A,">="&DATE(2018,1,1),Trans!$A:$A,"<"&EDATE(DATE(2018,1,1),1),Trans!$C:$C,"Debit") -> 0 | BG4: 1232836
A5: 2019-02 | B5: =SUMIFS(Trans!$D:$D,Trans!$F:$F,$B$1,Trans!$I:$I,$A5,Trans!$C:$C,"Debit") -> 0 | C5: =SUMIFS(Trans!$D:$D,Trans!$F:$F,C$1,Trans!$I:$I,$A5,Trans!$C:$C,"Debit") -> 0 | D5: =SUMIFS(Trans!$D:$D,Trans!$F:$F,D$1,Trans!$I:$I,$A5,Trans!$C:$C,"Debit") -> 0 | E5: =SUMIFS(Trans!$D:$D,Trans!$F:$F,E$1,Trans!$I:$I,$A5,Trans!$C:$C,"Debit") -> 0 | F5: =SUMIFS(Trans!$D:$D,Trans!$F:$F,F$1,Trans!$I:$I,$A5,Trans!$C:$C,"Debit") -> 0 | G5: =SUMIFS(Trans!$D:$D,Trans!$H:$H,G$1,Trans!$I:$I,$A5,Trans!$C:$C,"Debit") -> 0 | H5: =SUMIFS(Trans!$D:$D,Trans!$G:$G,H$1,Trans!$I:$I,$A5,Trans!$C:$C,"Debit") -> 0 | I5: =SUMIFS(Trans!$D:$D,Trans!$G:$G,I$1,Trans!$I:$I,$A5,Trans!$C:$C,"Debit") -> 0 | J5: =SUMIFS(Trans!$D:$D,Trans!$G:$G,J$1,Trans!$I:$I,$A5,Trans!$C:$C,"Debit") -> 0 | K5: =SUMIFS(Trans!$D:$D,Trans!$G:$G,K$1,Trans!$I:$I,$A5,Trans!$C:$C,"Debit") -> 0 | M5: =SUMIFS(Trans!$D:$D,Trans!$G:$G,M$1,Trans!$I:$I,$A5,Trans!$C:$C,"Debit") -> 0 | N5: =SUMIFS(Trans!$D:$D,Trans!$G:$G,N$1,Trans!$I:$I,$A5,Trans!$C:$C,"Debit") -> 0 | O5: =SUMIFS(Trans!$D:$D,Trans!$G:$G,E$1,Trans!$I:$I,$A20,Trans!$C:$C,"Debit") -> 0 | P5: =SUMIFS(Trans!$D:$D,Trans!$G:$G,M$1,Trans!$I:$I,$A20,Trans!$C:$C,"Debit")-SUMIFS(Trans!$D:$D,Trans!$G:$G,AX$1,Trans!$I:$I,$A20,Trans!$C:$C,"Credit") -> 0 | AF5: 70000 | AH5: =SUMIFS(Trans!$D:$D,Trans!$G:$G,AH$1,Trans!$I:$I,$A5,Trans!$C:$C,"Credit") -> 0 | AN5: =SUMIFS(Trans!$D:$D,Trans!$G:$G,AN$1,Trans!$I:$I,$A5,Trans!$C:$C,"Debit") -> 0 | AO5: =SUMIFS(Trans!$D:$D,Trans!$G:$G,AO$1,Trans!$I:$I,$A5,Trans!$C:$C,"Credit") -> 0 | AP5: =AO5-AN5 -> 0 | AQ5: =SUMIFS(Trans!$D:$D,Trans!$G:$G,AQ$1,Trans!$I:$I,$A5,Trans!$C:$C,"Debit") -> 0 | AR5: =SUMIFS(Trans!$D:$D,Trans!$G:$G,AR$1,Trans!$I:$I,$A5,Trans!$C:$C,"Credit") -> 0 | AU5: =SUMIFS(Trans!$D:$D,Trans!$G:$G,AU$1,Trans!$I:$I,$A5,Trans!$C:$C,"Debit") -> 0 | AV5: =SUM(SUMIFS(Trans!$D:$D,Trans!$H:$H,{"LC","DC","Customs duty","Freight ","Insurance","Related"},Trans!$I:$I,$A5,Trans!$C:$C,"Debit")) -> 0 | AW5: =SUMIFS(Trans!$D:$D,Trans!$G:$G,AQ$1,Trans!$I:$I,$A5,Trans!$C:$C,"Debit") -> 0 | AX5: =SUMIFS(Trans!$D:$D,Trans!$G:$G,AX$1,Trans!$I:$I,$A5,Trans!$C:$C,"Debit")-SUMIFS(Trans!$D:$D,Trans!$G:$G,#REF!,Trans!$I:$I,$A5,Trans!$C:$C,"Credit") -> 0 | AY5: =SUMIFS(Trans!$D:$D,Trans!#REF!,#REF!,Trans!$C:$C,"Debit") -> #REF! | BD5: 2018-02 | BE5: =SUMIFS(Trans!$D:$D,Trans!$A:$A,">="&DATE(2018,2,1),Trans!$A:$A,"<"&EDATE(DATE(2018,2,1),1),Trans!$C:$C,"Credit") -> 0 | BF5: =SUMIFS(Trans!$D:$D,Trans!$A:$A,">="&DATE(2018,2,1),Trans!$A:$A,"<"&EDATE(DATE(2018,2,1),1),Trans!$C:$C,"Debit") -> 0 | BG5: 1385458
A6: 2019-03 | B6: =SUMIFS(Trans!$D:$D,Trans!$F:$F,$B$1,Trans!$I:$I,$A6,Trans!$C:$C,"Debit") -> 0 | C6: =SUMIFS(Trans!$D:$D,Trans!$F:$F,C$1,Trans!$I:$I,$A6,Trans!$C:$C,"Debit") -> 0 | D6: =SUMIFS(Trans!$D:$D,Trans!$F:$F,D$1,Trans!$I:$I,$A6,Trans!$C:$C,"Debit") -> 0 | E6: =SUMIFS(Trans!$D:$D,Trans!$F:$F,E$1,Trans!$I:$I,$A6,Trans!$C:$C,"Debit") -> 0 | F6: =SUMIFS(Trans!$D:$D,Trans!$F:$F,F$1,Trans!$I:$I,$A6,Trans!$C:$C,"Debit") -> 0 | G6: =SUMIFS(Trans!$D:$D,Trans!$H:$H,G$1,Trans!$I:$I,$A6,Trans!$C:$C,"Debit") -> 0 | H6: =SUMIFS(Trans!$D:$D,Trans!$G:$G,H$1,Trans!$I:$I,$A6,Trans!$C:$C,"Debit") -> 0 | I6: =SUMIFS(Trans!$D:$D,Trans!$G:$G,I$1,Trans!$I:$I,$A6,Trans!$C:$C,"Debit") -> 0 | J6: =SUMIFS(Trans!$D:$D,Trans!$G:$G,J$1,Trans!$I:$I,$A6,Trans!$C:$C,"Debit") -> 0 | K6: =SUMIFS(Trans!$D:$D,Trans!$G:$G,K$1,Trans!$I:$I,$A6,Trans!$C:$C,"Debit") -> 0 | M6: =SUMIFS(Trans!$D:$D,Trans!$G:$G,M$1,Trans!$I:$I,$A6,Trans!$C:$C,"Debit") -> 0 | N6: =SUMIFS(Trans!$D:$D,Trans!$G:$G,N$1,Trans!$I:$I,$A6,Trans!$C:$C,"Debit") -> 0 | O6: =SUMIFS(Trans!$D:$D,Trans!$G:$G,E$1,Trans!$I:$I,$A21,Trans!$C:$C,"Debit") -> 0 | P6: =SUMIFS(Trans!$D:$D,Trans!$G:$G,M$1,Trans!$I:$I,$A21,Trans!$C:$C,"Debit")-SUMIFS(Trans!$D:$D,Trans!$G:$G,AX$1,Trans!$I:$I,$A21,Trans!$C:$C,"Credit") -> 0 | AF6: 20000 | AH6: =SUMIFS(Trans!$D:$D,Trans!$G:$G,AH$1,Trans!$I:$I,$A6,Trans!$C:$C,"Credit") -> 0 | AN6: =SUMIFS(Trans!$D:$D,Trans!$G:$G,AN$1,Trans!$I:$I,$A6,Trans!$C:$C,"Debit") -> 0 | AO6: =SUMIFS(Trans!$D:$D,Trans!$G:$G,AO$1,Trans!$I:$I,$A6,Trans!$C:$C,"Credit") -> 0 | AP6: =AO6-AN6 -> 0 | AQ6: =SUMIFS(Trans!$D:$D,Trans!$G:$G,AQ$1,Trans!$I:$I,$A6,Trans!$C:$C,"Debit") -> 0 | AR6: =SUMIFS(Trans!$D:$D,Trans!$G:$G,AR$1,Trans!$I:$I,$A6,Trans!$C:$C,"Credit") -> 0 | AU6: =SUMIFS(Trans!$D:$D,Trans!$G:$G,AU$1,Trans!$I:$I,$A6,Trans!$C:$C,"Debit") -> 0 | AV6: =SUM(SUMIFS(Trans!$D:$D,Trans!$H:$H,{"LC","DC","Customs duty","Freight ","Insurance","Related"},Trans!$I:$I,$A6,Trans!$C:$C,"Debit")) -> 0 | AW6: =SUMIFS(Trans!$D:$D,Trans!$G:$G,AQ$1,Trans!$I:$I,$A6,Trans!$C:$C,"Debit") -> 0 | AX6: =SUMIFS(Trans!$D:$D,Trans!$G:$G,AX$1,Trans!$I:$I,$A6,Trans!$C:$C,"Debit")-SUMIFS(Trans!$D:$D,Trans!$G:$G,#REF!,Trans!$I:$I,$A6,Trans!$C:$C,"Credit") -> 0 | AY6: =SUMIFS(Trans!$D:$D,Trans!#REF!,#REF!,Trans!$C:$C,"Debit") -> #REF! | BD6: 2018-03 | BE6: =SUMIFS(Trans!$D:$D,Trans!$A:$A,">="&DATE(2018,3,1),Trans!$A:$A,"<"&EDATE(DATE(2018,3,1),1),Trans!$C:$C,"Credit") -> 0 | BF6: =SUMIFS(Trans!$D:$D,Trans!$A:$A,">="&DATE(2018,3,1),Trans!$A:$A,"<"&EDATE(DATE(2018,3,1),1),Trans!$C:$C,"Debit") -> 0 | BG6: ='A1'!BB13 -> 0
A7: 2019-04 | B7: =SUMIFS(Trans!$D:$D,Trans!$F:$F,$B$1,Trans!$I:$I,$A7,Trans!$C:$C,"Debit") -> 0 | C7: =SUMIFS(Trans!$D:$D,Trans!$F:$F,C$1,Trans!$I:$I,$A7,Trans!$C:$C,"Debit") -> 0 | D7: =SUMIFS(Trans!$D:$D,Trans!$F:$F,D$1,Trans!$I:$I,$A7,Trans!$C:$C,"Debit") -> 0 | E7: =SUMIFS(Trans!$D:$D,Trans!$F:$F,E$1,Trans!$I:$I,$A7,Trans!$C:$C,"Debit") -> 0 | F7: =SUMIFS(Trans!$D:$D,Trans!$F:$F,F$1,Trans!$I:$I,$A7,Trans!$C:$C,"Debit") -> 0 | G7: =SUMIFS(Trans!$D:$D,Trans!$H:$H,G$1,Trans!$I:$I,$A7,Trans!$C:$C,"Debit") -> 0 | H7: =SUMIFS(Trans!$D:$D,Trans!$G:$G,H$1,Trans!$I:$I,$A7,Trans!$C:$C,"Debit") -> 0 | I7: =SUMIFS(Trans!$D:$D,Trans!$G:$G,I$1,Trans!$I:$I,$A7,Trans!$C:$C,"Debit") -> 0 | J7: =SUMIFS(Trans!$D:$D,Trans!$G:$G,J$1,Trans!$I:$I,$A7,Trans!$C:$C,"Debit") -> 0 | K7: =SUMIFS(Trans!$D:$D,Trans!$G:$G,K$1,Trans!$I:$I,$A7,Trans!$C:$C,"Debit") -> 0 | M7: =SUMIFS(Trans!$D:$D,Trans!$G:$G,M$1,Trans!$I:$I,$A7,Trans!$C:$C,"Debit") -> 0 | N7: =SUMIFS(Trans!$D:$D,Trans!$G:$G,N$1,Trans!$I:$I,$A7,Trans!$C:$C,"Debit") -> 0 | O7: =SUMIFS(Trans!$D:$D,Trans!$G:$G,E$1,Trans!$I:$I,$A22,Trans!$C:$C,"Debit") -> 0 | P7: =SUMIFS(Trans!$D:$D,Trans!$G:$G,M$1,Trans!$I:$I,$A22,Trans!$C:$C,"Debit")-SUMIFS(Trans!$D:$D,Trans!$G:$G,AX$1,Trans!$I:$I,$A22,Trans!$C:$C,"Credit") -> 0 | AF7: =AF6+AF5+AF4+AF3 -> 177000 | AH7: =SUMIFS(Trans!$D:$D,Trans!$G:$G,AH$1,Trans!$I:$I,$A7,Trans!$C:$C,"Credit") -> 0 | AN7: =SUMIFS(Trans!$D:$D,Trans!$G:$G,AN$1,Trans!$I:$I,$A7,Trans!$C:$C,"Debit") -> 0 | AO7: =SUMIFS(Trans!$D:$D,Trans!$G:$G,AO$1,Trans!$I:$I,$A7,Trans!$C:$C,"Credit") -> 0 | AP7: =AO7-AN7 -> 0 | AQ7: =SUMIFS(Trans!$D:$D,Trans!$G:$G,AQ$1,Trans!$I:$I,$A7,Trans!$C:$C,"Debit") -> 0 | AR7: =SUMIFS(Trans!$D:$D,Trans!$G:$G,AR$1,Trans!$I:$I,$A7,Trans!$C:$C,"Credit") -> 0 | AU7: =SUMIFS(Trans!$D:$D,Trans!$G:$G,AU$1,Trans!$I:$I,$A7,Trans!$C:$C,"Debit") -> 0 | AV7: =SUM(SUMIFS(Trans!$D:$D,Trans!$H:$H,{"LC","DC","Customs duty","Freight ","Insurance","Related"},Trans!$I:$I,$A7,Trans!$C:$C,"Debit")) -> 0 | AW7: =SUMIFS(Trans!$D:$D,Trans!$G:$G,AQ$1,Trans!$I:$I,$A7,Trans!$C:$C,"Debit") -> 0 | AX7: =SUMIFS(Trans!$D:$D,Trans!$G:$G,AX$1,Trans!$I:$I,$A7,Trans!$C:$C,"Debit")-SUMIFS(Trans!$D:$D,Trans!$G:$G,#REF!,Trans!$I:$I,$A7,Trans!$C:$C,"Credit") -> 0 | AY7: =SUMIFS(Trans!$D:$D,Trans!#REF!,#REF!,Trans!$C:$C,"Debit") -> #REF! | BD7: 2018-04 | BE7: =SUMIFS(Trans!$D:$D,Trans!$A:$A,">="&DATE(2018,4,1),Trans!$A:$A,"<"&EDATE(DATE(2018,4,1),1),Trans!$C:$C,"Credit") -> 0 | BF7: =SUMIFS(Trans!$D:$D,Trans!$A:$A,">="&DATE(2018,4,1),Trans!$A:$A,"<"&EDATE(DATE(2018,4,1),1),Trans!$C:$C,"Debit") -> 0
A8: 2019-05 | B8: =SUMIFS(Trans!$D:$D,Trans!$F:$F,$B$1,Trans!$I:$I,$A8,Trans!$C:$C,"Debit") -> 0 | C8: =SUMIFS(Trans!$D:$D,Trans!$F:$F,C$1,Trans!$I:$I,$A8,Trans!$C:$C,"Debit") -> 0 | D8: =SUMIFS(Trans!$D:$D,Trans!$F:$F,D$1,Trans!$I:$I,$A8,Trans!$C:$C,"Debit") -> 0 | E8: =SUMIFS(Trans!$D:$D,Trans!$F:$F,E$1,Trans!$I:$I,$A8,Trans!$C:$C,"Debit") -> 0 | F8: =SUMIFS(Trans!$D:$D,Trans!$F:$F,F$1,Trans!$I:$I,$A8,Trans!$C:$C,"Debit") -> 0 | G8: =SUMIFS(Trans!$D:$D,Trans!$H:$H,G$1,Trans!$I:$I,$A8,Trans!$C:$C,"Debit") -> 0 | H8: =SUMIFS(Trans!$D:$D,Trans!$G:$G,H$1,Trans!$I:$I,$A8,Trans!$C:$C,"Debit") -> 0 | I8: =SUMIFS(Trans!$D:$D,Trans!$G:$G,I$1,Trans!$I:$I,$A8,Trans!$C:$C,"Debit") -> 0 | J8: =SUMIFS(Trans!$D:$D,Trans!$G:$G,J$1,Trans!$I:$I,$A8,Trans!$C:$C,"Debit") -> 0 | K8: =SUMIFS(Trans!$D:$D,Trans!$G:$G,K$1,Trans!$I:$I,$A8,Trans!$C:$C,"Debit") -> 0 | M8: =SUMIFS(Trans!$D:$D,Trans!$G:$G,M$1,Trans!$I:$I,$A8,Trans!$C:$C,"Debit") -> 0 | N8: =SUMIFS(Trans!$D:$D,Trans!$G:$G,N$1,Trans!$I:$I,$A8,Trans!$C:$C,"Debit") -> 0 | O8: =SUMIFS(Trans!$D:$D,Trans!$G:$G,E$1,Trans!$I:$I,$A23,Trans!$C:$C,"Debit") -> 0 | P8: =SUMIFS(Trans!$D:$D,Trans!$G:$G,M$1,Trans!$I:$I,$A23,Trans!$C:$C,"Debit")-SUMIFS(Trans!$D:$D,Trans!$G:$G,AX$1,Trans!$I:$I,$A23,Trans!$C:$C,"Credit") -> 0 | AH8: =SUMIFS(Trans!$D:$D,Trans!$G:$G,AH$1,Trans!$I:$I,$A8,Trans!$C:$C,"Credit") -> 0 | AN8: =SUMIFS(Trans!$D:$D,Trans!$G:$G,AN$1,Trans!$I:$I,$A8,Trans!$C:$C,"Debit") -> 0 | AO8: =SUMIFS(Trans!$D:$D,Trans!$G:$G,AO$1,Trans!$I:$I,$A8,Trans!$C:$C,"Credit") -> 0 | AP8: =AO8-AN8 -> 0 | AQ8: =SUMIFS(Trans!$D:$D,Trans!$G:$G,AQ$1,Trans!$I:$I,$A8,Trans!$C:$C,"Debit") -> 0 | AR8: =SUMIFS(Trans!$D:$D,Trans!$G:$G,AR$1,Trans!$I:$I,$A8,Trans!$C:$C,"Credit") -> 0 | AU8: =SUMIFS(Trans!$D:$D,Trans!$G:$G,AU$1,Trans!$I:$I,$A8,Trans!$C:$C,"Debit") -> 0 | AV8: =SUM(SUMIFS(Trans!$D:$D,Trans!$H:$H,{"LC","DC","Customs duty","Freight ","Insurance","Related"},Trans!$I:$I,$A8,Trans!$C:$C,"Debit")) -> 0 | AW8: =SUMIFS(Trans!$D:$D,Trans!$G:$G,AQ$1,Trans!$I:$I,$A8,Trans!$C:$C,"Debit") -> 0 | AX8: =SUMIFS(Trans!$D:$D,Trans!$G:$G,AX$1,Trans!$I:$I,$A8,Trans!$C:$C,"Debit")-SUMIFS(Trans!$D:$D,Trans!$G:$G,#REF!,Trans!$I:$I,$A8,Trans!$C:$C,"Credit") -> 0 | AY8: =SUMIFS(Trans!$D:$D,Trans!#REF!,#REF!,Trans!$C:$C,"Debit") -> #REF! | BD8: 2018-05 | BE8: =SUMIFS(Trans!$D:$D,Trans!$A:$A,">="&DATE(2018,5,1),Trans!$A:$A,"<"&EDATE(DATE(2018,5,1),1),Trans!$C:$C,"Credit") -> 0 | BF8: =SUMIFS(Trans!$D:$D,Trans!$A:$A,">="&DATE(2018,5,1),Trans!$A:$A,"<"&EDATE(DATE(2018,5,1),1),Trans!$C:$C,"Debit") -> 0
A9: 2019-06 | B9: =SUMIFS(Trans!$D:$D,Trans!$F:$F,$B$1,Trans!$I:$I,$A9,Trans!$C:$C,"Debit") -> 0 | C9: =SUMIFS(Trans!$D:$D,Trans!$F:$F,C$1,Trans!$I:$I,$A9,Trans!$C:$C,"Debit") -> 0 | D9: =SUMIFS(Trans!$D:$D,Trans!$F:$F,D$1,Trans!$I:$I,$A9,Trans!$C:$C,"Debit") -> 0 | E9: =SUMIFS(Trans!$D:$D,Trans!$F:$F,E$1,Trans!$I:$I,$A9,Trans!$C:$C,"Debit") -> 0 | F9: =SUMIFS(Trans!$D:$D,Trans!$F:$F,F$1,Trans!$I:$I,$A9,Trans!$C:$C,"Debit") -> 0 | G9: =SUMIFS(Trans!$D:$D,Trans!$H:$H,G$1,Trans!$I:$I,$A9,Trans!$C:$C,"Debit") -> 0 | H9: =SUMIFS(Trans!$D:$D,Trans!$G:$G,H$1,Trans!$I:$I,$A9,Trans!$C:$C,"Debit") -> 0 | I9: =SUMIFS(Trans!$D:$D,Trans!$G:$G,I$1,Trans!$I:$I,$A9,Trans!$C:$C,"Debit") -> 0 | J9: =SUMIFS(Trans!$D:$D,Trans!$G:$G,J$1,Trans!$I:$I,$A9,Trans!$C:$C,"Debit") -> 0 | K9: =SUMIFS(Trans!$D:$D,Trans!$G:$G,K$1,Trans!$I:$I,$A9,Trans!$C:$C,"Debit") -> 0 | M9: =SUMIFS(Trans!$D:$D,Trans!$G:$G,M$1,Trans!$I:$I,$A9,Trans!$C:$C,"Debit") -> 0 | N9: =SUMIFS(Trans!$D:$D,Trans!$G:$G,N$1,Trans!$I:$I,$A9,Trans!$C:$C,"Debit") -> 0 | O9: =SUMIFS(Trans!$D:$D,Trans!$G:$G,E$1,Trans!$I:$I,$A24,Trans!$C:$C,"Debit") -> 0 | P9: =SUMIFS(Trans!$D:$D,Trans!$G:$G,M$1,Trans!$I:$I,$A24,Trans!$C:$C,"Debit")-SUMIFS(Trans!$D:$D,Trans!$G:$G,AX$1,Trans!$I:$I,$A24,Trans!$C:$C,"Credit") -> 0 | AH9: =SUMIFS(Trans!$D:$D,Trans!$G:$G,AH$1,Trans!$I:$I,$A9,Trans!$C:$C,"Credit") -> 0 | AN9: =SUMIFS(Trans!$D:$D,Trans!$G:$G,AN$1,Trans!$I:$I,$A9,Trans!$C:$C,"Debit") -> 0 | AO9: =SUMIFS(Trans!$D:$D,Trans!$G:$G,AO$1,Trans!$I:$I,$A9,Trans!$C:$C,"Credit") -> 0 | AP9: =AO9-AN9 -> 0 | AQ9: =SUMIFS(Trans!$D:$D,Trans!$G:$G,AQ$1,Trans!$I:$I,$A9,Trans!$C:$C,"Debit") -> 0 | AR9: =SUMIFS(Trans!$D:$D,Trans!$G:$G,AR$1,Trans!$I:$I,$A9,Trans!$C:$C,"Credit") -> 0 | AU9: =SUMIFS(Trans!$D:$D,Trans!$G:$G,AU$1,Trans!$I:$I,$A9,Trans!$C:$C,"Debit") -> 0 | AV9: =SUM(SUMIFS(Trans!$D:$D,Trans!$H:$H,{"LC","DC","Customs duty","Freight ","Insurance","Related"},Trans!$I:$I,$A9,Trans!$C:$C,"Debit")) -> 0 | AW9: =SUMIFS(Trans!$D:$D,Trans!$G:$G,AQ$1,Trans!$I:$I,$A9,Trans!$C:$C,"Debit") -> 0 | AX9: =SUMIFS(Trans!$D:$D,Trans!$G:$G,AX$1,Trans!$I:$I,$A9,Trans!$C:$C,"Debit")-SUMIFS(Trans!$D:$D,Trans!$G:$G,#REF!,Trans!$I:$I,$A9,Trans!$C:$C,"Credit") -> 0 | AY9: =SUMIFS(Trans!$D:$D,Trans!#REF!,#REF!,Trans!$C:$C,"Debit") -> #REF! | BD9: 2018-06 | BE9: =SUMIFS(Trans!$D:$D,Trans!$A:$A,">="&DATE(2018,6,1),Trans!$A:$A,"<"&EDATE(DATE(2018,6,1),1),Trans!$C:$C,"Credit") -> 0 | BF9: =SUMIFS(Trans!$D:$D,Trans!$A:$A,">="&DATE(2018,6,1),Trans!$A:$A,"<"&EDATE(DATE(2018,6,1),1),Trans!$C:$C,"Debit") -> 0
A10: 2019-07 | B10: =SUMIFS(Trans!$D:$D,Trans!$F:$F,$B$1,Trans!$I:$I,$A10,Trans!$C:$C,"Debit") -> 0 | C10: =SUMIFS(Trans!$D:$D,Trans!$F:$F,C$1,Trans!$I:$I,$A10,Trans!$C:$C,"Debit") -> 0 | D10: =SUMIFS(Trans!$D:$D,Trans!$F:$F,D$1,Trans!$I:$I,$A10,Trans!$C:$C,"Debit") -> 0 | E10: =SUMIFS(Trans!$D:$D,Trans!$F:$F,E$1,Trans!$I:$I,$A10,Trans!$C:$C,"Debit") -> 0 | F10: =SUMIFS(Trans!$D:$D,Trans!$F:$F,F$1,Trans!$I:$I,$A10,Trans!$C:$C,"Debit") -> 0 | G10: =SUMIFS(Trans!$D:$D,Trans!$H:$H,G$1,Trans!$I:$I,$A10,Trans!$C:$C,"Debit") -> 0 | H10: =SUMIFS(Trans!$D:$D,Trans!$G:$G,H$1,Trans!$I:$I,$A10,Trans!$C:$C,"Debit") -> 0 | I10: =SUMIFS(Trans!$D:$D,Trans!$G:$G,I$1,Trans!$I:$I,$A10,Trans!$C:$C,"Debit") -> 0 | J10: =SUMIFS(Trans!$D:$D,Trans!$G:$G,J$1,Trans!$I:$I,$A10,Trans!$C:$C,"Debit") -> 0 | K10: =SUMIFS(Trans!$D:$D,Trans!$G:$G,K$1,Trans!$I:$I,$A10,Trans!$C:$C,"Debit") -> 0 | M10: =SUMIFS(Trans!$D:$D,Trans!$G:$G,M$1,Trans!$I:$I,$A10,Trans!$C:$C,"Debit") -> 0 | N10: =SUMIFS(Trans!$D:$D,Trans!$G:$G,N$1,Trans!$I:$I,$A10,Trans!$C:$C,"Debit") -> 0 | O10: =SUMIFS(Trans!$D:$D,Trans!$G:$G,E$1,Trans!$I:$I,$A25,Trans!$C:$C,"Debit") -> 0 | P10: =SUMIFS(Trans!$D:$D,Trans!$G:$G,M$1,Trans!$I:$I,$A25,Trans!$C:$C,"Debit")-SUMIFS(Trans!$D:$D,Trans!$G:$G,AX$1,Trans!$I:$I,$A25,Trans!$C:$C,"Credit") -> 0 | AH10: =SUMIFS(Trans!$D:$D,Trans!$G:$G,AH$1,Trans!$I:$I,$A10,Trans!$C:$C,"Credit") -> 0 | AN10: =SUMIFS(Trans!$D:$D,Trans!$G:$G,AN$1,Trans!$I:$I,$A10,Trans!$C:$C,"Debit") -> 0 | AO10: =SUMIFS(Trans!$D:$D,Trans!$G:$G,AO$1,Trans!$I:$I,$A10,Trans!$C:$C,"Credit") -> 0 | AP10: =AO10-AN10 -> 0 | AQ10: =SUMIFS(Trans!$D:$D,Trans!$G:$G,AQ$1,Trans!$I:$I,$A10,Trans!$C:$C,"Debit") -> 0 | AR10: =SUMIFS(Trans!$D:$D,Trans!$G:$G,AR$1,Trans!$I:$I,$A10,Trans!$C:$C,"Credit") -> 0 | AU10: =SUMIFS(Trans!$D:$D,Trans!$G:$G,AU$1,Trans!$I:$I,$A10,Trans!$C:$C,"Debit") -> 0 | AV10: =SUM(SUMIFS(Trans!$D:$D,Trans!$H:$H,{"LC","DC","Customs duty","Freight ","Insurance","Related"},Trans!$I:$I,$A10,Trans!$C:$C,"Debit")) -> 0 | AW10: =SUMIFS(Trans!$D:$D,Trans!$G:$G,AQ$1,Trans!$I:$I,$A10,Trans!$C:$C,"Debit") -> 0 | AX10: =SUMIFS(Trans!$D:$D,Trans!$G:$G,AX$1,Trans!$I:$I,$A10,Trans!$C:$C,"Debit")-SUMIFS(Trans!$D:$D,Trans!$G:$G,#REF!,Trans!$I:$I,$A10,Trans!$C:$C,"Credit") -> 0 | AY10: =SUMIFS(Trans!$D:$D,Trans!#REF!,#REF!,Trans!$C:$C,"Debit") -> #REF! | BD10: 2018-07 | BE10: =SUMIFS(Trans!$D:$D,Trans!$A:$A,">="&DATE(2018,7,1),Trans!$A:$A,"<"&EDATE(DATE(2018,7,1),1),Trans!$C:$C,"Credit") -> 0 | BF10: =SUMIFS(Trans!$D:$D,Trans!$A:$A,">="&DATE(2018,7,1),Trans!$A:$A,"<"&EDATE(DATE(2018,7,1),1),Trans!$C:$C,"Debit") -> 0
A11: 2019-08 | B11: =SUMIFS(Trans!$D:$D,Trans!$F:$F,$B$1,Trans!$I:$I,$A11,Trans!$C:$C,"Debit") -> 0 | C11: =SUMIFS(Trans!$D:$D,Trans!$F:$F,C$1,Trans!$I:$I,$A11,Trans!$C:$C,"Debit") -> 0 | D11: =SUMIFS(Trans!$D:$D,Trans!$F:$F,D$1,Trans!$I:$I,$A11,Trans!$C:$C,"Debit") -> 0 | E11: =SUMIFS(Trans!$D:$D,Trans!$F:$F,E$1,Trans!$I:$I,$A11,Trans!$C:$C,"Debit") -> 0 | F11: =SUMIFS(Trans!$D:$D,Trans!$F:$F,F$1,Trans!$I:$I,$A11,Trans!$C:$C,"Debit") -> 0 | G11: =SUMIFS(Trans!$D:$D,Trans!$H:$H,G$1,Trans!$I:$I,$A11,Trans!$C:$C,"Debit") -> 0 | H11: =SUMIFS(Trans!$D:$D,Trans!$G:$G,H$1,Trans!$I:$I,$A11,Trans!$C:$C,"Debit") -> 0 | I11: =SUMIFS(Trans!$D:$D,Trans!$G:$G,I$1,Trans!$I:$I,$A11,Trans!$C:$C,"Debit") -> 0 | J11: =SUMIFS(Trans!$D:$D,Trans!$G:$G,J$1,Trans!$I:$I,$A11,Trans!$C:$C,"Debit") -> 0 | K11: =SUMIFS(Trans!$D:$D,Trans!$G:$G,K$1,Trans!$I:$I,$A11,Trans!$C:$C,"Debit") -> 0 | M11: =SUMIFS(Trans!$D:$D,Trans!$G:$G,M$1,Trans!$I:$I,$A11,Trans!$C:$C,"Debit") -> 0 | N11: =SUMIFS(Trans!$D:$D,Trans!$G:$G,N$1,Trans!$I:$I,$A11,Trans!$C:$C,"Debit") -> 0 | O11: =SUMIFS(Trans!$D:$D,Trans!$G:$G,E$1,Trans!$I:$I,$A26,Trans!$C:$C,"Debit") -> 0 | P11: =SUMIFS(Trans!$D:$D,Trans!$G:$G,M$1,Trans!$I:$I,$A26,Trans!$C:$C,"Debit")-SUMIFS(Trans!$D:$D,Trans!$G:$G,AX$1,Trans!$I:$I,$A26,Trans!$C:$C,"Credit") -> 0 | AH11: =SUMIFS(Trans!$D:$D,Trans!$G:$G,AH$1,Trans!$I:$I,$A11,Trans!$C:$C,"Credit") -> 0 | AN11: =SUMIFS(Trans!$D:$D,Trans!$G:$G,AN$1,Trans!$I:$I,$A11,Trans!$C:$C,"Debit") -> 0 | AO11: =SUMIFS(Trans!$D:$D,Trans!$G:$G,AO$1,Trans!$I:$I,$A11,Trans!$C:$C,"Credit") -> 0 | AP11: =AO11-AN11 -> 0 | AQ11: =SUMIFS(Trans!$D:$D,Trans!$G:$G,AQ$1,Trans!$I:$I,$A11,Trans!$C:$C,"Debit") -> 0 | AR11: =SUMIFS(Trans!$D:$D,Trans!$G:$G,AR$1,Trans!$I:$I,$A11,Trans!$C:$C,"Credit") -> 0 | AU11: =SUMIFS(Trans!$D:$D,Trans!$G:$G,AU$1,Trans!$I:$I,$A11,Trans!$C:$C,"Debit") -> 0 | AV11: =SUM(SUMIFS(Trans!$D:$D,Trans!$H:$H,{"LC","DC","Customs duty","Freight ","Insurance","Related"},Trans!$I:$I,$A11,Trans!$C:$C,"Debit")) -> 0 | AW11: =SUMIFS(Trans!$D:$D,Trans!$G:$G,AQ$1,Trans!$I:$I,$A11,Trans!$C:$C,"Debit") -> 0 | AX11: =SUMIFS(Trans!$D:$D,Trans!$G:$G,AX$1,Trans!$I:$I,$A11,Trans!$C:$C,"Debit")-SUMIFS(Trans!$D:$D,Trans!$G:$G,#REF!,Trans!$I:$I,$A11,Trans!$C:$C,"Credit") -> 0 | AY11: =SUMIFS(Trans!$D:$D,Trans!#REF!,#REF!,Trans!$C:$C,"Debit") -> #REF! | BD11: 2018-08 | BE11: =SUMIFS(Trans!$D:$D,Trans!$A:$A,">="&DATE(2018,8,1),Trans!$A:$A,"<"&EDATE(DATE(2018,8,1),1),Trans!$C:$C,"Credit") -> 0 | BF11: =SUMIFS(Trans!$D:$D,Trans!$A:$A,">="&DATE(2018,8,1),Trans!$A:$A,"<"&EDATE(DATE(2018,8,1),1),Trans!$C:$C,"Debit") -> 0
A12: 2019-09 | B12: =SUMIFS(Trans!$D:$D,Trans!$F:$F,$B$1,Trans!$I:$I,$A12,Trans!$C:$C,"Debit") -> 0 | C12: =SUMIFS(Trans!$D:$D,Trans!$F:$F,C$1,Trans!$I:$I,$A12,Trans!$C:$C,"Debit") -> 0 | D12: =SUMIFS(Trans!$D:$D,Trans!$F:$F,D$1,Trans!$I:$I,$A12,Trans!$C:$C,"Debit") -> 0 | E12: =SUMIFS(Trans!$D:$D,Trans!$F:$F,E$1,Trans!$I:$I,$A12,Trans!$C:$C,"Debit") -> 0 | F12: =SUMIFS(Trans!$D:$D,Trans!$F:$F,F$1,Trans!$I:$I,$A12,Trans!$C:$C,"Debit") -> 0 | G12: =SUMIFS(Trans!$D:$D,Trans!$H:$H,G$1,Trans!$I:$I,$A12,Trans!$C:$C,"Debit") -> 0 | H12: =SUMIFS(Trans!$D:$D,Trans!$G:$G,H$1,Trans!$I:$I,$A12,Trans!$C:$C,"Debit") -> 0 | I12: =SUMIFS(Trans!$D:$D,Trans!$G:$G,I$1,Trans!$I:$I,$A12,Trans!$C:$C,"Debit") -> 0 | J12: =SUMIFS(Trans!$D:$D,Trans!$G:$G,J$1,Trans!$I:$I,$A12,Trans!$C:$C,"Debit") -> 0 | K12: =SUMIFS(Trans!$D:$D,Trans!$G:$G,K$1,Trans!$I:$I,$A12,Trans!$C:$C,"Debit") -> 0 | M12: =SUMIFS(Trans!$D:$D,Trans!$G:$G,M$1,Trans!$I:$I,$A12,Trans!$C:$C,"Debit") -> 0 | N12: =SUMIFS(Trans!$D:$D,Trans!$G:$G,N$1,Trans!$I:$I,$A12,Trans!$C:$C,"Debit") -> 0 | O12: =SUMIFS(Trans!$D:$D,Trans!$G:$G,E$1,Trans!$I:$I,$A27,Trans!$C:$C,"Debit") -> 0 | P12: =SUMIFS(Trans!$D:$D,Trans!$G:$G,M$1,Trans!$I:$I,$A27,Trans!$C:$C,"Debit")-SUMIFS(Trans!$D:$D,Trans!$G:$G,AX$1,Trans!$I:$I,$A27,Trans!$C:$C,"Credit") -> 0 | AH12: =SUMIFS(Trans!$D:$D,Trans!$G:$G,AH$1,Trans!$I:$I,$A12,Trans!$C:$C,"Credit") -> 0 | AN12: =SUMIFS(Trans!$D:$D,Trans!$G:$G,AN$1,Trans!$I:$I,$A12,Trans!$C:$C,"Debit") -> 0 | AO12: =SUMIFS(Trans!$D:$D,Trans!$G:$G,AO$1,Trans!$I:$I,$A12,Trans!$C:$C,"Credit") -> 0 | AP12: =AO12-AN12 -> 0 | AQ12: =SUMIFS(Trans!$D:$D,Trans!$G:$G,AQ$1,Trans!$I:$I,$A12,Trans!$C:$C,"Debit") -> 0 | AR12: =SUMIFS(Trans!$D:$D,Trans!$G:$G,AR$1,Trans!$I:$I,$A12,Trans!$C:$C,"Credit") -> 0 | AU12: =SUMIFS(Trans!$D:$D,Trans!$G:$G,AU$1,Trans!$I:$I,$A12,Trans!$C:$C,"Debit") -> 0 | AV12: =SUM(SUMIFS(Trans!$D:$D,Trans!$H:$H,{"LC","DC","Customs duty","Freight ","Insurance","Related"},Trans!$I:$I,$A12,Trans!$C:$C,"Debit")) -> 0 | AW12: =SUMIFS(Trans!$D:$D,Trans!$G:$G,AQ$1,Trans!$I:$I,$A12,Trans!$C:$C,"Debit") -> 0 | AX12: =SUMIFS(Trans!$D:$D,Trans!$G:$G,AX$1,Trans!$I:$I,$A12,Trans!$C:$C,"Debit")-SUMIFS(Trans!$D:$D,Trans!$G:$G,#REF!,Trans!$I:$I,$A12,Trans!$C:$C,"Credit") -> 0 | AY12: =SUMIFS(Trans!$D:$D,Trans!#REF!,#REF!,Trans!$C:$C,"Debit") -> #REF! | BD12: 2018-09 | BE12: =SUMIFS(Trans!$D:$D,Trans!$A:$A,">="&DATE(2018,9,1),Trans!$A:$A,"<"&EDATE(DATE(2018,9,1),1),Trans!$C:$C,"Credit") -> 0 | BF12: =SUMIFS(Trans!$D:$D,Trans!$A:$A,">="&DATE(2018,9,1),Trans!$A:$A,"<"&EDATE(DATE(2018,9,1),1),Trans!$C:$C,"Debit") -> 0
A13: 2019-10 | B13: =SUMIFS(Trans!$D:$D,Trans!$F:$F,$B$1,Trans!$I:$I,$A13,Trans!$C:$C,"Debit") -> 0 | C13: =SUMIFS(Trans!$D:$D,Trans!$F:$F,C$1,Trans!$I:$I,$A13,Trans!$C:$C,"Debit") -> 0 | D13: =SUMIFS(Trans!$D:$D,Trans!$F:$F,D$1,Trans!$I:$I,$A13,Trans!$C:$C,"Debit") -> 0 | E13: =SUMIFS(Trans!$D:$D,Trans!$F:$F,E$1,Trans!$I:$I,$A13,Trans!$C:$C,"Debit") -> 0 | F13: =SUMIFS(Trans!$D:$D,Trans!$F:$F,F$1,Trans!$I:$I,$A13,Trans!$C:$C,"Debit") -> 0 | G13: =SUMIFS(Trans!$D:$D,Trans!$H:$H,G$1,Trans!$I:$I,$A13,Trans!$C:$C,"Debit") -> 0 | H13: =SUMIFS(Trans!$D:$D,Trans!$G:$G,H$1,Trans!$I:$I,$A13,Trans!$C:$C,"Debit") -> 0 | I13: =SUMIFS(Trans!$D:$D,Trans!$G:$G,I$1,Trans!$I:$I,$A13,Trans!$C:$C,"Debit") -> 0 | J13: =SUMIFS(Trans!$D:$D,Trans!$G:$G,J$1,Trans!$I:$I,$A13,Trans!$C:$C,"Debit") -> 0 | K13: =SUMIFS(Trans!$D:$D,Trans!$G:$G,K$1,Trans!$I:$I,$A13,Trans!$C:$C,"Debit") -> 0 | M13: =SUMIFS(Trans!$D:$D,Trans!$G:$G,M$1,Trans!$I:$I,$A13,Trans!$C:$C,"Debit") -> 0 | N13: =SUMIFS(Trans!$D:$D,Trans!$G:$G,N$1,Trans!$I:$I,$A13,Trans!$C:$C,"Debit") -> 0 | O13: =SUMIFS(Trans!$D:$D,Trans!$G:$G,E$1,Trans!$I:$I,$A28,Trans!$C:$C,"Debit") -> 0 | P13: =SUMIFS(Trans!$D:$D,Trans!$G:$G,M$1,Trans!$I:$I,$A28,Trans!$C:$C,"Debit")-SUMIFS(Trans!$D:$D,Trans!$G:$G,AX$1,Trans!$I:$I,$A28,Trans!$C:$C,"Credit") -> 0 | AH13: =SUMIFS(Trans!$D:$D,Trans!$G:$G,AH$1,Trans!$I:$I,$A13,Trans!$C:$C,"Credit") -> 0 | AN13: =SUMIFS(Trans!$D:$D,Trans!$G:$G,AN$1,Trans!$I:$I,$A13,Trans!$C:$C,"Debit") -> 0 | AO13: =SUMIFS(Trans!$D:$D,Trans!$G:$G,AO$1,Trans!$I:$I,$A13,Trans!$C:$C,"Credit") -> 0 | AP13: =AO13-AN13 -> 0 | AQ13: =SUMIFS(Trans!$D:$D,Trans!$G:$G,AQ$1,Trans!$I:$I,$A13,Trans!$C:$C,"Debit") -> 0 | AR13: =SUMIFS(Trans!$D:$D,Trans!$G:$G,AR$1,Trans!$I:$I,$A13,Trans!$C:$C,"Credit") -> 0 | AU13: =SUMIFS(Trans!$D:$D,Trans!$G:$G,AU$1,Trans!$I:$I,$A13,Trans!$C:$C,"Debit") -> 0 | AV13: =SUM(SUMIFS(Trans!$D:$D,Trans!$H:$H,{"LC","DC","Customs duty","Freight ","Insurance","Related"},Trans!$I:$I,$A13,Trans!$C:$C,"Debit")) -> 0 | AW13: =SUMIFS(Trans!$D:$D,Trans!$G:$G,AQ$1,Trans!$I:$I,$A13,Trans!$C:$C,"Debit") -> 0 | AX13: =SUMIFS(Trans!$D:$D,Trans!$G:$G,AX$1,Trans!$I:$I,$A13,Trans!$C:$C,"Debit")-SUMIFS(Trans!$D:$D,Trans!$G:$G,#REF!,Trans!$I:$I,$A13,Trans!$C:$C,"Credit") -> 0 | AY13: =SUMIFS(Trans!$D:$D,Trans!#REF!,#REF!,Trans!$C:$C,"Debit") -> #REF! | BD13: 2018-10 | BE13: =SUMIFS(Trans!$D:$D,Trans!$A:$A,">="&DATE(2018,10,1),Trans!$A:$A,"<"&EDATE(DATE(2018,10,1),1),Trans!$C:$C,"Credit") -> 0 | BF13: =SUMIFS(Trans!$D:$D,Trans!$A:$A,">="&DATE(2018,10,1),Trans!$A:$A,"<"&EDATE(DATE(2018,10,1),1),Trans!$C:$C,"Debit") -> 0
B14: =SUMIFS(Trans!$D:$D,Trans!$F:$F,$B$1,Trans!$I:$I,$A14,Trans!$C:$C,"Debit") -> 0 | C14: =SUM(C47+C46+#REF!+#REF!) -> #REF! | D14: =SUM(D47+D46+#REF!+#REF!) -> #REF! | E14: =SUM(E47+E46+#REF!+#REF!) -> #REF! | F14: =SUM(F47+F46+#REF!+#REF!) -> #REF! | G14: =SUM(G47+G46+#REF!+#REF!) -> #REF! | H14: =SUM(H47+H46+H45+H44) -> 0 | I14: =SUM(I47+I46+I45+I44) -> 0 | J14: =SUM(J47+J46+J45+J44) -> 0 | K14: =SUM(K47+K46+K45+K44) -> 0 | M14: =SUM(L47+L46+L45+L44) -> 0 | N14: =SUM(M47+M46+M45+M44) -> 0 | O14: =SUM(K62+K61+K60+K59) -> 0 | P14: =SUM(L62+L61+L60+L59) -> 0 | AH14: =SUM(AH47+AH46+AH45+AH44) -> 0 | AN14: =SUM(R47+R46+R45+R44) -> 0 | AO14: =SUM(S47+S46+S45+S44) -> 0 | AQ14: =SUM(U47+U46+U45+U44) -> 0 | AR14: =SUM(V47+V46+V45+V44) -> 0 | AU14: =SUM(Y47+Y46+Y45+Y44) -> 0 | AV14: =SUM(Z47+Z46+Z45+Z44) -> 0 | AW14: =SUM(AA47+AA46+AA45+AA44) -> 0 | AX14: =SUM(AB47+AB46+AB45+AB44) -> 0 | AY14: =SUMIFS(Trans!$D:$D,Trans!#REF!,#REF!,Trans!$C:$C,"Debit") -> #REF!
A16: Month | B16: Credit | C16: Cr Paid | D16: Cr Payable | E16: Loan | F16: Loan Paid | G16: L Payable | H16: T Liabelity
A17: 2018-11 | B17: =SUMIFS(Trans!$D:$D,Trans!$G:$G,B$1,Trans!$I:$I,$A17,Trans!$C:$C,"Debit") -> 0 | C17: =SUMIFS(Trans!$D:$D,Trans!$G:$G,C$1,Trans!$I:$I,$A17,Trans!$C:$C,"Credit") -> 0 | D17: =C17-B17 -> 0 | E17: =SUMIFS(Trans!$D:$D,Trans!$G:$G,E$1,Trans!$I:$I,$A17,Trans!$C:$C,"Debit") -> 0 | F17: =SUMIFS(Trans!$D:$D,Trans!$G:$G,F$1,Trans!$I:$I,$A17,Trans!$C:$C,"Credit") -> 0
A18: 2018-12 | B18: =SUMIFS(Trans!$D:$D,Trans!$G:$G,B$1,Trans!$I:$I,$A18,Trans!$C:$C,"Debit") -> 0 | C18: =SUMIFS(Trans!$D:$D,Trans!$G:$G,C$1,Trans!$I:$I,$A18,Trans!$C:$C,"Credit") -> 0 | D18: =C18-B18 -> 0 | E18: =SUMIFS(Trans!$D:$D,Trans!$G:$G,E$1,Trans!$I:$I,$A18,Trans!$C:$C,"Debit") -> 0 | F18: =SUMIFS(Trans!$D:$D,Trans!$G:$G,F$1,Trans!$I:$I,$A18,Trans!$C:$C,"Credit") -> 0
A19: 2019-01 | B19: =SUMIFS(Trans!$D:$D,Trans!$G:$G,B$1,Trans!$I:$I,$A19,Trans!$C:$C,"Debit") -> 0 | C19: =SUMIFS(Trans!$D:$D,Trans!$G:$G,C$1,Trans!$I:$I,$A19,Trans!$C:$C,"Credit") -> 0 | D19: =C19-B19 -> 0 | E19: =SUMIFS(Trans!$D:$D,Trans!$G:$G,E$1,Trans!$I:$I,$A19,Trans!$C:$C,"Debit") -> 0 | F19: =SUMIFS(Trans!$D:$D,Trans!$G:$G,F$1,Trans!$I:$I,$A19,Trans!$C:$C,"Credit") -> 0
A20: 2019-02 | B20: =SUMIFS(Trans!$D:$D,Trans!$G:$G,B$1,Trans!$I:$I,$A20,Trans!$C:$C,"Debit") -> 0 | C20: =SUMIFS(Trans!$D:$D,Trans!$G:$G,C$1,Trans!$I:$I,$A20,Trans!$C:$C,"Credit") -> 0 | D20: =C20-B20 -> 0 | E20: =SUMIFS(Trans!$D:$D,Trans!$G:$G,E$1,Trans!$I:$I,$A20,Trans!$C:$C,"Debit") -> 0 | F20: =SUMIFS(Trans!$D:$D,Trans!$G:$G,F$1,Trans!$I:$I,$A20,Trans!$C:$C,"Credit") -> 0
A21: 2019-03 | B21: =SUMIFS(Trans!$D:$D,Trans!$G:$G,B$1,Trans!$I:$I,$A21,Trans!$C:$C,"Debit") -> 0 | C21: =SUMIFS(Trans!$D:$D,Trans!$G:$G,C$1,Trans!$I:$I,$A21,Trans!$C:$C,"Credit") -> 0 | D21: =C21-B21 -> 0 | E21: =SUMIFS(Trans!$D:$D,Trans!$G:$G,E$1,Trans!$I:$I,$A21,Trans!$C:$C,"Debit") -> 0 | F21: =SUMIFS(Trans!$D:$D,Trans!$G:$G,F$1,Trans!$I:$I,$A21,Trans!$C:$C,"Credit") -> 0
A22: 2019-04 | B22: =SUMIFS(Trans!$D:$D,Trans!$G:$G,B$1,Trans!$I:$I,$A22,Trans!$C:$C,"Debit") -> 0 | C22: =SUMIFS(Trans!$D:$D,Trans!$G:$G,C$1,Trans!$I:$I,$A22,Trans!$C:$C,"Credit") -> 0 | D22: =C22-B22 -> 0 | E22: =SUMIFS(Trans!$D:$D,Trans!$G:$G,E$1,Trans!$I:$I,$A22,Trans!$C:$C,"Debit") -> 0 | F22: =SUMIFS(Trans!$D:$D,Trans!$G:$G,F$1,Trans!$I:$I,$A22,Trans!$C:$C,"Credit") -> 0
A23: 2019-05 | B23: =SUMIFS(Trans!$D:$D,Trans!$G:$G,B$1,Trans!$I:$I,$A23,Trans!$C:$C,"Debit") -> 0 | C23: =SUMIFS(Trans!$D:$D,Trans!$G:$G,C$1,Trans!$I:$I,$A23,Trans!$C:$C,"Credit") -> 0 | D23: =C23-B23 -> 0 | E23: =SUMIFS(Trans!$D:$D,Trans!$G:$G,E$1,Trans!$I:$I,$A23,Trans!$C:$C,"Debit") -> 0 | F23: =SUMIFS(Trans!$D:$D,Trans!$G:$G,F$1,Trans!$I:$I,$A23,Trans!$C:$C,"Credit") -> 0
A24: 2019-06 | B24: =SUMIFS(Trans!$D:$D,Trans!$G:$G,B$1,Trans!$I:$I,$A24,Trans!$C:$C,"Debit") -> 0 | C24: =SUMIFS(Trans!$D:$D,Trans!$G:$G,C$1,Trans!$I:$I,$A24,Trans!$C:$C,"Credit") -> 0 | D24: =C24-B24 -> 0 | E24: =SUMIFS(Trans!$D:$D,Trans!$G:$G,E$1,Trans!$I:$I,$A24,Trans!$C:$C,"Debit") -> 0 | F24: =SUMIFS(Trans!$D:$D,Trans!$G:$G,F$1,Trans!$I:$I,$A24,Trans!$C:$C,"Credit") -> 0
A25: 2019-07 | B25: =SUMIFS(Trans!$D:$D,Trans!$G:$G,B$1,Trans!$I:$I,$A25,Trans!$C:$C,"Debit") -> 0 | C25: =SUMIFS(Trans!$D:$D,Trans!$G:$G,C$1,Trans!$I:$I,$A25,Trans!$C:$C,"Credit") -> 0 | D25: =C25-B25 -> 0 | E25: =SUMIFS(Trans!$D:$D,Trans!$G:$G,E$1,Trans!$I:$I,$A25,Trans!$C:$C,"Debit") -> 0 | F25: =SUMIFS(Trans!$D:$D,Trans!$G:$G,F$1,Trans!$I:$I,$A25,Trans!$C:$C,"Credit") -> 0
A26: 2019-08 | B26: =SUMIFS(Trans!$D:$D,Trans!$G:$G,B$1,Trans!$I:$I,$A26,Trans!$C:$C,"Debit") -> 0 | C26: =SUMIFS(Trans!$D:$D,Trans!$G:$G,C$1,Trans!$I:$I,$A26,Trans!$C:$C,"Credit") -> 0 | D26: =C26-B26 -> 0 | E26: =SUMIFS(Trans!$D:$D,Trans!$G:$G,E$1,Trans!$I:$I,$A26,Trans!$C:$C,"Debit") -> 0 | F26: =SUMIFS(Trans!$D:$D,Trans!$G:$G,F$1,Trans!$I:$I,$A26,Trans!$C:$C,"Credit") -> 0
A27: 2019-09 | B27: =SUMIFS(Trans!$D:$D,Trans!$G:$G,B$1,Trans!$I:$I,$A27,Trans!$C:$C,"Debit") -> 0 | C27: =SUMIFS(Trans!$D:$D,Trans!$G:$G,C$1,Trans!$I:$I,$A27,Trans!$C:$C,"Credit") -> 0 | D27: =C27-B27 -> 0 | E27: =SUMIFS(Trans!$D:$D,Trans!$G:$G,E$1,Trans!$I:$I,$A27,Trans!$C:$C,"Debit") -> 0 | F27: =SUMIFS(Trans!$D:$D,Trans!$G:$G,F$1,Trans!$I:$I,$A27,Trans!$C:$C,"Credit") -> 0
A28: 2019-10 | B28: =SUMIFS(Trans!$D:$D,Trans!$G:$G,B$1,Trans!$I:$I,$A28,Trans!$C:$C,"Debit") -> 0 | C28: =SUMIFS(Trans!$D:$D,Trans!$G:$G,C$1,Trans!$I:$I,$A28,Trans!$C:$C,"Credit") -> 0 | D28: =C28-B28 -> 0 | E28: =SUMIFS(Trans!$D:$D,Trans!$G:$G,E$1,Trans!$I:$I,$A28,Trans!$C:$C,"Debit") -> 0 | F28: =SUMIFS(Trans!$D:$D,Trans!$G:$G,F$1,Trans!$I:$I,$A28,Trans!$C:$C,"Credit") -> 0
B29: =SUM(B62+B61+B60+B59) -> 0 | C29: =SUM(C62+C61+C60+C59) -> 0 | E29: =SUM(E62+E61+E60+E59) -> 0 | F29: =SUM(F62+F61+F60+F59) -> 0
A32: Month | B32: WHT | C32: Rev Tax | D32: Dividend | E32: Audit fee | F32: Whl Pur | G32: DC
A33: 2018-11 | B33: =SUMIFS(Trans!$D:$D,Trans!$H:$H,B$32,Trans!$I:$I,$A2,Trans!$C:$C,"Debit") -> 0 | C33: =SUMIFS(Trans!$D:$D,Trans!$H:$H,C$32,Trans!$I:$I,$A2,Trans!$C:$C,"Debit") -> 0 | D33: =SUMIFS(Trans!$D:$D,Trans!$H:$H,D$32,Trans!$I:$I,$A2,Trans!$C:$C,"Debit") -> 0 | E33: =SUMIFS(Trans!$D:$D,Trans!$H:$H,E$32,Trans!$I:$I,$A2,Trans!$C:$C,"Debit") -> 0 | F33: =SUMIFS(Trans!$D:$D,Trans!$G:$G,I$1,Trans!$I:$I,$A17,Trans!$C:$C,"Debit") -> 0 | G33: {=SUM(SUMIFS(Trans!$D:$D,Trans!$H:$H,{"LC","DC","Customs duty","Freight ","Insurance","Related"},Trans!$I:$I,$A17,Trans!$C:$C,"Debit"))} -> 0
A34: 2018-12 | B34: =SUMIFS(Trans!$D:$D,Trans!$H:$H,B$32,Trans!$I:$I,$A3,Trans!$C:$C,"Debit") -> 0 | C34: =SUMIFS(Trans!$D:$D,Trans!$H:$H,C$32,Trans!$I:$I,$A3,Trans!$C:$C,"Debit") -> 0 | D34: =SUMIFS(Trans!$D:$D,Trans!$H:$H,D$32,Trans!$I:$I,$A3,Trans!$C:$C,"Debit") -> 0 | E34: =SUMIFS(Trans!$D:$D,Trans!$H:$H,E$32,Trans!$I:$I,$A3,Trans!$C:$C,"Debit") -> 0 | F34: =SUMIFS(Trans!$D:$D,Trans!$G:$G,I$1,Trans!$I:$I,$A18,Trans!$C:$C,"Debit") -> 0 | G34: =SUM(SUMIFS(Trans!$D:$D,Trans!$H:$H,{"LC","DC","Customs duty","Freight ","Insurance","Related"},Trans!$I:$I,$A18,Trans!$C:$C,"Debit")) -> 0
A35: 2019-01 | B35: =SUMIFS(Trans!$D:$D,Trans!$H:$H,B$32,Trans!$I:$I,$A4,Trans!$C:$C,"Debit") -> 0 | C35: =SUMIFS(Trans!$D:$D,Trans!$H:$H,C$32,Trans!$I:$I,$A4,Trans!$C:$C,"Debit") -> 0 | D35: =SUMIFS(Trans!$D:$D,Trans!$H:$H,D$32,Trans!$I:$I,$A4,Trans!$C:$C,"Debit") -> 0 | E35: =SUMIFS(Trans!$D:$D,Trans!$H:$H,E$32,Trans!$I:$I,$A4,Trans!$C:$C,"Debit") -> 0 | F35: =SUMIFS(Trans!$D:$D,Trans!$G:$G,I$1,Trans!$I:$I,$A19,Trans!$C:$C,"Debit") -> 0 | G35: =SUM(SUMIFS(Trans!$D:$D,Trans!$H:$H,{"LC","DC","Customs duty","Freight ","Insurance","Related"},Trans!$I:$I,$A19,Trans!$C:$C,"Debit")) -> 0
A36: 2019-02 | B36: =SUMIFS(Trans!$D:$D,Trans!$H:$H,B$32,Trans!$I:$I,$A5,Trans!$C:$C,"Debit") -> 0 | C36: =SUMIFS(Trans!$D:$D,Trans!$H:$H,C$32,Trans!$I:$I,$A5,Trans!$C:$C,"Debit") -> 0 | D36: =SUMIFS(Trans!$D:$D,Trans!$H:$H,D$32,Trans!$I:$I,$A5,Trans!$C:$C,"Debit") -> 0 | E36: =SUMIFS(Trans!$D:$D,Trans!$H:$H,E$32,Trans!$I:$I,$A5,Trans!$C:$C,"Debit") -> 0 | F36: =SUMIFS(Trans!$D:$D,Trans!$G:$G,I$1,Trans!$I:$I,$A20,Trans!$C:$C,"Debit") -> 0 | G36: =SUM(SUMIFS(Trans!$D:$D,Trans!$H:$H,{"LC","DC","Customs duty","Freight ","Insurance","Related"},Trans!$I:$I,$A20,Trans!$C:$C,"Debit")) -> 0
A37: 2019-03 | B37: =SUMIFS(Trans!$D:$D,Trans!$H:$H,B$32,Trans!$I:$I,$A6,Trans!$C:$C,"Debit") -> 0 | C37: =SUMIFS(Trans!$D:$D,Trans!$H:$H,C$32,Trans!$I:$I,$A6,Trans!$C:$C,"Debit") -> 0 | D37: =SUMIFS(Trans!$D:$D,Trans!$H:$H,D$32,Trans!$I:$I,$A6,Trans!$C:$C,"Debit") -> 0 | E37: =SUMIFS(Trans!$D:$D,Trans!$H:$H,E$32,Trans!$I:$I,$A6,Trans!$C:$C,"Debit") -> 0 | F37: =SUMIFS(Trans!$D:$D,Trans!$G:$G,I$1,Trans!$I:$I,$A21,Trans!$C:$C,"Debit") -> 0 | G37: =SUM(SUMIFS(Trans!$D:$D,Trans!$H:$H,{"LC","DC","Customs duty","Freight ","Insurance","Related"},Trans!$I:$I,$A21,Trans!$C:$C,"Debit")) -> 0
A38: 2019-04 | B38: =SUMIFS(Trans!$D:$D,Trans!$H:$H,B$32,Trans!$I:$I,$A7,Trans!$C:$C,"Debit") -> 0 | C38: =SUMIFS(Trans!$D:$D,Trans!$H:$H,C$32,Trans!$I:$I,$A7,Trans!$C:$C,"Debit") -> 0 | D38: =SUMIFS(Trans!$D:$D,Trans!$H:$H,D$32,Trans!$I:$I,$A7,Trans!$C:$C,"Debit") -> 0 | E38: =SUMIFS(Trans!$D:$D,Trans!$H:$H,E$32,Trans!$I:$I,$A7,Trans!$C:$C,"Debit") -> 0 | F38: =SUMIFS(Trans!$D:$D,Trans!$G:$G,I$1,Trans!$I:$I,$A22,Trans!$C:$C,"Debit") -> 0 | G38: =SUM(SUMIFS(Trans!$D:$D,Trans!$H:$H,{"LC","DC","Customs duty","Freight ","Insurance","Related"},Trans!$I:$I,$A22,Trans!$C:$C,"Debit")) -> 0
A39: 2019-05 | B39: =SUMIFS(Trans!$D:$D,Trans!$H:$H,B$32,Trans!$I:$I,$A8,Trans!$C:$C,"Debit") -> 0 | C39: =SUMIFS(Trans!$D:$D,Trans!$H:$H,C$32,Trans!$I:$I,$A8,Trans!$C:$C,"Debit") -> 0 | D39: =SUMIFS(Trans!$D:$D,Trans!$H:$H,D$32,Trans!$I:$I,$A8,Trans!$C:$C,"Debit") -> 0 | E39: =SUMIFS(Trans!$D:$D,Trans!$H:$H,E$32,Trans!$I:$I,$A8,Trans!$C:$C,"Debit") -> 0 | F39: =SUMIFS(Trans!$D:$D,Trans!$G:$G,I$1,Trans!$I:$I,$A23,Trans!$C:$C,"Debit") -> 0 | G39: =SUM(SUMIFS(Trans!$D:$D,Trans!$H:$H,{"LC","DC","Customs duty","Freight ","Insurance","Related"},Trans!$I:$I,$A23,Trans!$C:$C,"Debit")) -> 0
A40: 2019-06 | B40: =SUMIFS(Trans!$D:$D,Trans!$H:$H,B$32,Trans!$I:$I,$A9,Trans!$C:$C,"Debit") -> 0 | C40: =SUMIFS(Trans!$D:$D,Trans!$H:$H,C$32,Trans!$I:$I,$A9,Trans!$C:$C,"Debit") -> 0 | D40: =SUMIFS(Trans!$D:$D,Trans!$H:$H,D$32,Trans!$I:$I,$A9,Trans!$C:$C,"Debit") -> 0 | E40: =SUMIFS(Trans!$D:$D,Trans!$H:$H,E$32,Trans!$I:$I,$A9,Trans!$C:$C,"Debit") -> 0 | F40: =SUMIFS(Trans!$D:$D,Trans!$G:$G,I$1,Trans!$I:$I,$A24,Trans!$C:$C,"Debit") -> 0 | G40: =SUM(SUMIFS(Trans!$D:$D,Trans!$H:$H,{"LC","DC","Customs duty","Freight ","Insurance","Related"},Trans!$I:$I,$A24,Trans!$C:$C,"Debit")) -> 0
A41: 2019-07 | B41: =SUMIFS(Trans!$D:$D,Trans!$H:$H,B$32,Trans!$I:$I,$A10,Trans!$C:$C,"Debit") -> 0 | C41: =SUMIFS(Trans!$D:$D,Trans!$H:$H,C$32,Trans!$I:$I,$A10,Trans!$C:$C,"Debit") -> 0 | D41: =SUMIFS(Trans!$D:$D,Trans!$H:$H,D$32,Trans!$I:$I,$A10,Trans!$C:$C,"Debit") -> 0 | E41: =SUMIFS(Trans!$D:$D,Trans!$H:$H,E$32,Trans!$I:$I,$A10,Trans!$C:$C,"Debit") -> 0 | F41: =SUMIFS(Trans!$D:$D,Trans!$G:$G,I$1,Trans!$I:$I,$A25,Trans!$C:$C,"Debit") -> 0 | G41: =SUM(SUMIFS(Trans!$D:$D,Trans!$H:$H,{"LC","DC","Customs duty","Freight ","Insurance","Related"},Trans!$I:$I,$A25,Trans!$C:$C,"Debit")) -> 0
A42: 2019-08 | B42: =SUMIFS(Trans!$D:$D,Trans!$H:$H,B$32,Trans!$I:$I,$A11,Trans!$C:$C,"Debit") -> 0 | C42: =SUMIFS(Trans!$D:$D,Trans!$H:$H,C$32,Trans!$I:$I,$A11,Trans!$C:$C,"Debit") -> 0 | D42: =SUMIFS(Trans!$D:$D,Trans!$H:$H,D$32,Trans!$I:$I,$A11,Trans!$C:$C,"Debit") -> 0 | E42: =SUMIFS(Trans!$D:$D,Trans!$H:$H,E$32,Trans!$I:$I,$A11,Trans!$C:$C,"Debit") -> 0 | F42: =SUMIFS(Trans!$D:$D,Trans!$G:$G,I$1,Trans!$I:$I,$A26,Trans!$C:$C,"Debit") -> 0 | G42: =SUM(SUMIFS(Trans!$D:$D,Trans!$H:$H,{"LC","DC","Customs duty","Freight ","Insurance","Related"},Trans!$I:$I,$A26,Trans!$C:$C,"Debit")) -> 0
A43: 2019-09 | B43: =SUMIFS(Trans!$D:$D,Trans!$H:$H,B$32,Trans!$I:$I,$A12,Trans!$C:$C,"Debit") -> 0 | C43: =SUMIFS(Trans!$D:$D,Trans!$H:$H,C$32,Trans!$I:$I,$A12,Trans!$C:$C,"Debit") -> 0 | D43: =SUMIFS(Trans!$D:$D,Trans!$H:$H,D$32,Trans!$I:$I,$A12,Trans!$C:$C,"Debit") -> 0 | E43: =SUMIFS(Trans!$D:$D,Trans!$H:$H,E$32,Trans!$I:$I,$A12,Trans!$C:$C,"Debit") -> 0 | F43: =SUMIFS(Trans!$D:$D,Trans!$G:$G,I$1,Trans!$I:$I,$A27,Trans!$C:$C,"Debit") -> 0 | G43: =SUM(SUMIFS(Trans!$D:$D,Trans!$H:$H,{"LC","DC","Customs duty","Freight ","Insurance","Related"},Trans!$I:$I,$A27,Trans!$C:$C,"Debit")) -> 0 | AX43: Investment | AY43: =SUMIFS(Trans!$D:$D,Trans!#REF!,AX43,Trans!$C:$C,"Debit") -> #REF!
...

Sheet Sheet1
B1: BANK & CASH FLOW DASHBOARD
B3: ="Live view of bank balances, inflows/outflows and monthly trend | Source: Trans ledger | Generated "&TEXT(TODAY(),"mmmm d, yyyy") -> Live view of bank balances, inflows/outflows and monthly trend | Source: Trans ledger | Generated July 15, 2026
B5: TOTAL CASH POSITION | E5: TOTAL INFLOW (CREDIT) | H5: TOTAL OUTFLOW (DEBIT) | K5: NET CASH FLOW
B6: =SUM(F16:F25) -> 2513678.6 | E6: =SUMIF([1]Trans!$C:$C,"Credit",[1]Trans!$D:$D) -> 2703700 | H6: =SUMIF([1]Trans!$C:$C,"Debit",[1]Trans!$D:$D) -> 130000 | K6: =E6-H6 -> 2573700
B7: ="Across "&COUNTA($B16:$B25)&" bank accounts" -> Across 10 bank accounts | E7: =COUNTIF([1]Trans!$C:$C,"Credit")&" credit transactions" -> 3 credit transactions | H7: =COUNTIF([1]Trans!$C:$C,"Debit")&" debit transactions" -> 2 debit transactions | K7: =IF(K6>=0,"Positive flow","Negative flow") -> Positive flow
B9: TRANSACTIONS RECORDED | E9: AVERAGE TRANSACTION SIZE | H9: HIGHEST BANK BALANCE | K9: LOWEST BANK BALANCE
B10: =COUNTA([1]Trans!$D$2:$D$5000) -> 5 | E10: =IFERROR(AVERAGE([1]Trans!$D$2:$D$5000),0) -> 566740 | H10: =INDEX($B$16:$B$25,MATCH(MAX($F$16:$F$25),$F$16:$F$25,0)) -> Total | K10: =INDEX($B$16:$B$25,MATCH(MIN($F$16:$F$25),$F$16:$F$25,0)) -> BOA
B11: ="Since ledger inception" -> Since ledger inception | E11: ="Per recorded transaction" -> Per recorded transaction | H11: =TEXT(MAX($F$16:$F$25),"#,##0")&" ETB" -> 1,752,081 ETB | K11: =TEXT(MIN($F$16:$F$25),"#,##0")&" ETB" -> 1,354 ETB
B13: CASH POSITION BY BANK
B14: Bank | C14: Opening Bal. | D14: Credit | E14: Debit | F14: Closing Bal. | G14: % of Total
B15: =[1]List!N2 -> CBE | C15: =[1]List!O2 -> 584984 | D15: =IFERROR(SUMIFS(Trans!$D:$D,Trans!$B:$B,$B15,Trans!$C:$C,"Credit"),0) -> 535500 | E15: =IFERROR(SUMIFS([1]Trans!$D:$D,[1]Trans!$B:$B,$B15,[1]Trans!$C:$C,"Debit"),0) -> 130000 | F15: =C15+D15-E15 -> 990484 | G15: =IFERROR(F15/$F$25,0) -> 0.56531852
B16: =[1]List!N3 -> COOP | C16: =[1]List!O3 -> 71149 | D16: =IFERROR(SUMIFS([1]Trans!$D:$D,[1]Trans!$B:$B,$B16,[1]Trans!$C:$C,"Credit"),0) -> 0 | E16: =IFERROR(SUMIFS([1]Trans!$D:$D,[1]Trans!$B:$B,$B16,[1]Trans!$C:$C,"Debit"),0) -> 0 | F16: =C16+D16-E16 -> 71149 | G16: =IFERROR(F16/$F$25,0) -> 0.040608275
B17: =[1]List!N4 -> AIB | C17: =[1]List!O4 -> 151882.3 | D17: =IFERROR(SUMIFS([1]Trans!$D:$D,[1]Trans!$B:$B,$B17,[1]Trans!$C:$C,"Credit"),0) -> 0 | E17: =IFERROR(SUMIFS([1]Trans!$D:$D,[1]Trans!$B:$B,$B17,[1]Trans!$C:$C,"Debit"),0) -> 0 | F17: =C17+D17-E17 -> 151882.3 | G17: =IFERROR(F17/$F$25,0) -> 0.086686788
B18: =[1]List!N5 -> BOA | C18: =[1]List!O5 -> 1354 | D18: =IFERROR(SUMIFS([1]Trans!$D:$D,[1]Trans!$B:$B,$B18,[1]Trans!$C:$C,"Credit"),0) -> 0 | E18: =IFERROR(SUMIFS([1]Trans!$D:$D,[1]Trans!$B:$B,$B18,[1]Trans!$C:$C,"Debit"),0) -> 0 | F18: =C18+D18-E18 -> 1354 | G18: =IFERROR(F18/$F$25,0) -> 0.00077279519
B19: =[1]List!N6 -> Berhan | C19: =[1]List!O6 -> 5928 | D19: =IFERROR(SUMIFS([1]Trans!$D:$D,[1]Trans!$B:$B,$B19,[1]Trans!$C:$C,"Credit"),0) -> 203700 | E19: =IFERROR(SUMIFS([1]Trans!$D:$D,[1]Trans!$B:$B,$B19,[1]Trans!$C:$C,"Debit"),0) -> 0 | F19: =C19+D19-E19 -> 209628 | G19: =IFERROR(F19/$F$25,0) -> 0.11964513
B20: =[1]List!N7 -> Siinqe | C20: =[1]List!O7 -> 225631 | D20: =IFERROR(SUMIFS([1]Trans!$D:$D,[1]Trans!$B:$B,$B20,[1]Trans!$C:$C,"Credit"),0) -> 0 | E20: =IFERROR(SUMIFS([1]Trans!$D:$D,[1]Trans!$B:$B,$B20,[1]Trans!$C:$C,"Debit"),0) -> 0 | F20: =C20+D20-E20 -> 225631 | G20: =IFERROR(F20/$F$25,0) -> 0.12877884
B21: =[1]List!N8 -> Zemen | C21: =[1]List!O8 -> 6581 | D21: =IFERROR(SUMIFS([1]Trans!$D:$D,[1]Trans!$B:$B,$B21,[1]Trans!$C:$C,"Credit"),0) -> 0 | E21: =IFERROR(SUMIFS([1]Trans!$D:$D,[1]Trans!$B:$B,$B21,[1]Trans!$C:$C,"Debit"),0) -> 0 | F21: =C21+D21-E21 -> 6581 | G21: =IFERROR(F21/$F$25,0) -> 0.0037561042
B22: =[1]List!N9 -> OIB | C22: =[1]List!O9 -> 1792 | D22: =IFERROR(SUMIFS([1]Trans!$D:$D,[1]Trans!$B:$B,$B22,[1]Trans!$C:$C,"Credit"),0) -> 0 | E22: =IFERROR(SUMIFS([1]Trans!$D:$D,[1]Trans!$B:$B,$B22,[1]Trans!$C:$C,"Debit"),0) -> 0 | F22: =C22+D22-E22 -> 1792 | G22: =IFERROR(F22/$F$25,0) -> 0.0010227836
B23: =[1]List!N10 -> Hibrate | C23: =[1]List!O10 -> 2795 | D23: =IFERROR(SUMIFS([1]Trans!$D:$D,[1]Trans!$B:$B,$B23,[1]Trans!$C:$C,"Credit"),0) -> 0 | E23: =IFERROR(SUMIFS([1]Trans!$D:$D,[1]Trans!$B:$B,$B23,[1]Trans!$C:$C,"Debit"),0) -> 0 | F23: =C23+D23-E23 -> 2795 | G23: =IFERROR(F23/$F$25,0) -> 0.0015952456
B24: =[1]List!N11 -> Dashin | C24: =[1]List!O11 -> 90785 | D24: =IFERROR(SUMIFS([1]Trans!$D:$D,[1]Trans!$B:$B,$B24,[1]Trans!$C:$C,"Credit"),0) -> 0 | E24: =IFERROR(SUMIFS([1]Trans!$D:$D,[1]Trans!$B:$B,$B24,[1]Trans!$C:$C,"Debit"),0) -> 0 | F24: =C24+D24-E24 -> 90785 | G24: =IFERROR(F24/$F$25,0) -> 0.051815518
B25: Total | C25: =SUM(C15:C24) -> 1142881.3 | D25: =SUM(D15:D24) -> 739200 | E25: =SUM(E15:E24) -> 130000 | F25: =SUM(F15:F24) -> 1752081.3 | G25: =SUM(G15:G24) -> 1
B27: MONTHLY CASH FLOW TREND (Ethiopian Calendar Month)
B28: Month | C28: Inflow (Credit) | D28: Outflow (Debit) | E28: Net Cash Flow
B29: 2018-11 | C29: =SUMIFS([1]Trans!$D:$D,[1]Trans!$I:$I,$B29,[1]Trans!$C:$C,"Credit") -> 2703700 | D29: =SUMIFS([1]Trans!$D:$D,[1]Trans!$I:$I,$B29,[1]Trans!$C:$C,"Debit") -> 130000 | E29: =C29-D29 -> 2573700
B30: 2018-12 | C30: =SUMIFS([1]Trans!$D:$D,[1]Trans!$I:$I,$B30,[1]Trans!$C:$C,"Credit") -> 0 | D30: =SUMIFS([1]Trans!$D:$D,[1]Trans!$I:$I,$B30,[1]Trans!$C:$C,"Debit") -> 0 | E30: =C30-D30 -> 0
B31: 2019-01 | C31: =SUMIFS([1]Trans!$D:$D,[1]Trans!$I:$I,$B31,[1]Trans!$C:$C,"Credit") -> 0 | D31: =SUMIFS([1]Trans!$D:$D,[1]Trans!$I:$I,$B31,[1]Trans!$C:$C,"Debit") -> 0 | E31: =C31-D31 -> 0
B32: 2019-02 | C32: =SUMIFS([1]Trans!$D:$D,[1]Trans!$I:$I,$B32,[1]Trans!$C:$C,"Credit") -> 0 | D32: =SUMIFS([1]Trans!$D:$D,[1]Trans!$I:$I,$B32,[1]Trans!$C:$C,"Debit") -> 0 | E32: =C32-D32 -> 0
B33: 2019-03 | C33: =SUMIFS([1]Trans!$D:$D,[1]Trans!$I:$I,$B33,[1]Trans!$C:$C,"Credit") -> 0 | D33: =SUMIFS([1]Trans!$D:$D,[1]Trans!$I:$I,$B33,[1]Trans!$C:$C,"Debit") -> 0 | E33: =C33-D33 -> 0
B34: 2019-04 | C34: =SUMIFS([1]Trans!$D:$D,[1]Trans!$I:$I,$B34,[1]Trans!$C:$C,"Credit") -> 0 | D34: =SUMIFS([1]Trans!$D:$D,[1]Trans!$I:$I,$B34,[1]Trans!$C:$C,"Debit") -> 0 | E34: =C34-D34 -> 0
B35: 2019-05 | C35: =SUMIFS([1]Trans!$D:$D,[1]Trans!$I:$I,$B35,[1]Trans!$C:$C,"Credit") -> 0 | D35: =SUMIFS([1]Trans!$D:$D,[1]Trans!$I:$I,$B35,[1]Trans!$C:$C,"Debit") -> 0 | E35: =C35-D35 -> 0
B36: 2019-06 | C36: =SUMIFS([1]Trans!$D:$D,[1]Trans!$I:$I,$B36,[1]Trans!$C:$C,"Credit") -> 0 | D36: =SUMIFS([1]Trans!$D:$D,[1]Trans!$I:$I,$B36,[1]Trans!$C:$C,"Debit") -> 0 | E36: =C36-D36 -> 0
B37: 2019-07 | C37: =SUMIFS([1]Trans!$D:$D,[1]Trans!$I:$I,$B37,[1]Trans!$C:$C,"Credit") -> 0 | D37: =SUMIFS([1]Trans!$D:$D,[1]Trans!$I:$I,$B37,[1]Trans!$C:$C,"Debit") -> 0 | E37: =C37-D37 -> 0
B38: 2019-08 | C38: =SUMIFS([1]Trans!$D:$D,[1]Trans!$I:$I,$B38,[1]Trans!$C:$C,"Credit") -> 0 | D38: =SUMIFS([1]Trans!$D:$D,[1]Trans!$I:$I,$B38,[1]Trans!$C:$C,"Debit") -> 0 | E38: =C38-D38 -> 0
B39: 2019-09 | C39: =SUMIFS([1]Trans!$D:$D,[1]Trans!$I:$I,$B39,[1]Trans!$C:$C,"Credit") -> 0 | D39: =SUMIFS([1]Trans!$D:$D,[1]Trans!$I:$I,$B39,[1]Trans!$C:$C,"Debit") -> 0 | E39: =C39-D39 -> 0
B40: 2019-10 | C40: =SUMIFS([1]Trans!$D:$D,[1]Trans!$I:$I,$B40,[1]Trans!$C:$C,"Credit") -> 0 | D40: =SUMIFS([1]Trans!$D:$D,[1]Trans!$I:$I,$B40,[1]Trans!$C:$C,"Debit") -> 0 | E40: =C40-D40 -> 0
B41: Total | C41: =SUM(C29:C40) -> 2703700 | D41: =SUM(D29:D40) -> 130000 | E41: =SUM(E29:E40) -> 2573700
B43: CASH FLOW BY CATEGORY (source: Trans ledger)
B44: Income Sources | E44: Operating Expenses | H44: Non-Operating / Payables | K44: Taxes & COGS
B45: =[1]List!$A3 -> Ca sales | C45: =IFERROR(SUMIF([1]Trans!$E:$E,B45,[1]Trans!$D:$D),0) -> 0 | E45: =[1]List!$B3 -> Salaries | F45: =IFERROR(SUMIF([1]Trans!$F:$F,E45,[1]Trans!$D:$D),0) -> 0 | H45: =[1]List!$C3 -> Purchase | I45: =IFERROR(SUMIF([1]Trans!$G:$G,H45,[1]Trans!$D:$D),0) -> 0 | K45: =[1]List!$D3 -> WHT | L45: =IFERROR(SUMIF([1]Trans!$H:$H,K45,[1]Trans!$D:$D),0) -> 0
B46: =[1]List!$A4 -> Collected | C46: =IFERROR(SUMIF([1]Trans!$E:$E,B46,[1]Trans!$D:$D),0) -> 203700 | E46: =[1]List!$B4 -> Utilities | F46: =IFERROR(SUMIF([1]Trans!$F:$F,E46,[1]Trans!$D:$D),0) -> 0 | H46: =[1]List!$C4 -> Incentive | I46: =IFERROR(SUMIF([1]Trans!$G:$G,H46,[1]Trans!$D:$D),0) -> 0 | K46: =[1]List!$D4 -> Rev Tax | L46: =IFERROR(SUMIF([1]Trans!$H:$H,K46,[1]Trans!$D:$D),0) -> 0
...

Sheet Sheet4
A1: Row Labels | B1: Sum of Amount
A2: Jacaranda | B2: 209400
A3: Grand Total | B3: 209400
C22: =GETPIVOTDATA("Amount",$A$1) -> 209400
A27: Credit Status | B27: Sum of Amount
A28: FP need | B28: 209400 | C28: =GETPIVOTDATA("Amount",$A$27,"C Status","Due soon") -> #REF!
A29: Grand Total | B29: 209400 | C29: =GETPIVOTDATA("Amount",$A$27,"C Status","FP need") -> 209400
C30: =GETPIVOTDATA("Amount",$A$27,"C Status","Over Due") -> #REF!
C31: =GETPIVOTDATA("Amount",$A$27,"C Status","Pending") -> #REF!
C32: =GETPIVOTDATA("Amount",$A$27,"C Status","Settled") -> #REF!
C33: =GETPIVOTDATA("Amount",$A$27) -> 209400
A44: Row Labels | B44: Sum of Amount2
A45: ሰኔ | B45: 60000
A46: ግንቦት | B46: 149400
A47: Grand Total | B47: 209400
C49: =GETPIVOTDATA("Amount",$A$44) -> 209400
A54: Row Labels | B54: Sum of Amount
A55: Credit | B55: 209400
A56: Grand Total | B56: 209400

Sheet D

Sheet CreditS (2)
A1: SN | B1: Buyer | C1: Amount | D1: Date | E1: DD | F1: P Status | G1: C Status | H1: Month | I1: CD | J1: DSO | K1: DOP | L1: Expd | M1: Rrk | N1: PP | O1: Left | Q1: =TODAY() -> 46218 | R1: Over Due | S1: =_xlfn.XLOOKUP(R1,G2:G1005,F2:F1005) -> Credit | T1: Parcial | U1: T credit | W1: Etc Sold Date | X1: Mth | Y1: Month of Sold | Z1: Etc Paid date | AA1: MthP | AB1: Etc Paid Month | AD1: WK Sold | AE1: WK Paid
A2: 1 | B2: Eman | C2: 62000 | D2: 46104 | E2: =IF(D2="","",IF(F2="paid",0,I2-J2)) -> -54 | F2: Credit | G2: =IF(F2="Paid","Settled",IF(E2="","",IF(E2<0,"Over Due",IF(E2<=10,"Due soon",IF(E2<=20,"FP need",IF(E2<=30,"Pending","Pending")))))) -> Over Due | H2: =IFERROR(CHOOSE($X2,"መስከረም","ጥቅምት","ህዳር ","ታህሳስ ","ጥር ","የካቲት ","መጋቢት ","ሚይዚያ ","ግንቦት ","ሰኔ ","ሐምሌ ","ነሐሴ ","Pagume"),"") -> መጋቢት | I2: 60 | J2: =IF(D2="","-",$Q$1-D2) -> 114 | L2: =IF(E2="","",$Q$1+E2) -> 46164 | M2: ሰኔ18 | O2: {=SUMPRODUCT(($F2:$F2="Parcial")*ABS($C2:$C2-$N2:$N2))} -> 0 | R2: =SUMIFS(C2:C1005,G2:G1005,R1) -> 1048130 | S2: =SUMIFS(C2:C1000,F2:F1000,S1) -> 2627080 | T2: =SUMIFS(O2:O1005,F2:F1005,T1) -> 13050 | U2: =T2+S2 -> 2640130 | W2: =IF($D2="","",_xlfn.LET(_xlpm.gDate,D2,_xlpm.ethYear,IF(_xlpm.gDate>=DATE(YEAR(_xlpm.gDate),9,11),YEAR(_xlpm.gDate)-7,YEAR(_xlpm.gDate)-8),_xlpm.prevEthYear,_xlpm.ethYear-1,_xlpm.startDate,IF(_xlpm.gDate>=DATE(YEAR(_xlpm.gDate),9,11),DATE(YEAR(_xlpm.gDate),9,11)+IF(MOD(_xlpm.prevEthYear,4)=3,1,0),DATE(YEAR(_xlpm.gDate)-1,9,11)+IF(MOD(_xlpm.prevEthYear,4)=3,1,0)),_xlpm.dayOfYear,_xlpm.gDate-_xlpm.startDate+1,_xlpm.month,IF(_xlpm.dayOfYear<=360,CEILING(_xlpm.dayOfYear/30,1),13),_xlpm.day,IF(_xlpm.month=13,_xlpm.dayOfYear-360,_xlpm.dayOfYear-(_xlpm.month-1)*30),TEXT(_xlpm.ethYear,"0000")&"-"&TEXT(_xlpm.month,"00")&"-"&TEXT(_xlpm.day,"00"))) -> 2018-07-14 | X2: =IF($W2="","",TEXT($W2,"mm")) -> 07 | Y2: =IFERROR(CHOOSE(X2,"መስከረም","ጥቅምት","ህዳር ","ታህሳስ ","ጥር ","የካቲት ","መጋቢት18","ሚይዚያ ","ግንቦት18","ሰኔ18","ሐምሌ ","ነሐሴ ","Pagume"),"") -> መጋቢት18 | Z2: =IF($K2="","",_xlfn.LET(_xlpm.gDate,K2,_xlpm.ethYear,IF(_xlpm.gDate>=DATE(YEAR(_xlpm.gDate),9,11),YEAR(_xlpm.gDate)-7,YEAR(_xlpm.gDate)-8),_xlpm.prevEthYear,_xlpm.ethYear-1,_xlpm.startDate,IF(_xlpm.gDate>=DATE(YEAR(_xlpm.gDate),9,11),DATE(YEAR(_xlpm.gDate),9,11)+IF(MOD(_xlpm.prevEthYear,4)=3,1,0),DATE(YEAR(_xlpm.gDate)-1,9,11)+IF(MOD(_xlpm.prevEthYear,4)=3,1,0)),_xlpm.dayOfYear,_xlpm.gDate-_xlpm.startDate+1,_xlpm.month,IF(_xlpm.dayOfYear<=360,CEILING(_xlpm.dayOfYear/30,1),13),_xlpm.day,IF(_xlpm.month=13,_xlpm.dayOfYear-360,_xlpm.dayOfYear-(_xlpm.month-1)*30),TEXT(_xlpm.ethYear,"0000")&"-"&TEXT(_xlpm.month,"00")&"-"&TEXT(_xlpm.day,"00"))) | AA2: =IF($Z2="","",TEXT($Z2,"mm")) | AB2: =IFERROR(CHOOSE(AA2,"መስከረም","ጥቅምት","ህዳር ","ታህሳስ ","ጥር ","የካቲት ","መጋቢት ","ሚይዚያ ","ግንቦት ","ሰኔ ","ሐምሌ ","ነሐሴ ","Pagume"),"") | AD2: =IF($D2="","",YEAR(D2)&"-W"&WEEKNUM(D2,2)) -> 2026-W13 | AE2: =IF($K2="","",YEAR(K2)&"-W"&WEEKNUM(K2,2))
